Workbook
Name client_code: 'Πρόσκληση'!$B$4
Name invitation_ref: 'Πρόσκληση'!$B$5
Name inv_date: 'Πρόσκληση'!$B$6
Name deadline: 'Πρόσκληση'!$B$7
Name unsealing: 'Πρόσκληση'!$B$8
Name years: 'Πρόσκληση'!$B$9
Name sign_date: 'Πρόσκληση'!$B$10
Name contract_end: 'Πρόσκληση'!$B$11
Name award_docs_date: 'Πρόσκληση'!$B$12
Name annex_label: 'Πρόσκληση'!$B$13
Name offer_valid_until: 'Πρόσκληση'!$B$16
Name guar_p_until: 'Πρόσκληση'!$B$17
Name guar_g_until: 'Πρόσκληση'!$B$18
Name gg_months: 'Πρόσκληση'!$B$19
Name fuel_cons: 'Πρόσκληση'!$B$22
Name fuel_price: 'Πρόσκληση'!$B$23
Name wear: 'Πρόσκληση'!$B$24
Name opp_rate: 'Πρόσκληση'!$B$25
Name ins_year: 'Πρόσκληση'!$B$26
Name bank_rate: 'Πρόσκληση'!$B$27
Name bank_fee: 'Πρόσκληση'!$B$28
Name paid_share: 'Πρόσκληση'!$B$29
Name fuel_scn: 'Πρόσκληση'!$B$30
Name ded_base: 'Πρόσκληση'!$B$33
Name ded_rate: 'Πρόσκληση'!$B$34
Name gp_rate: 'Πρόσκληση'!$B$35
Name gg_rate: 'Πρόσκληση'!$B$36
Name gp_months: 'Πρόσκληση'!$B$37
Name inputs_ok: 'Πρόσκληση'!$B$39
Name offer_lines: 'Προσφορά'!$E$23
Name offer_errors: 'Προσφορά'!$E$24
Name offer_guarantee_check: 'Προσφορά'!$E$29
Name docs_offer_open: 'Έγγραφα'!$D$3

Sheet Οδηγίες
A1: Βήμα 4: Concierge Φάσης Β, ένα αρχείο ανά πελάτη και πρόσκληση
A2: Οδηγός: discovery/concierge-phase-b-2026.md. Τύποι go/no-go: docs/plan.md §5. Κανόνες εγγράφων: tenders/pkm-meth-student-transport-dsa-2026/requirements.csv και sop.md (Φάση Β). Το § είναι ενότητα της διακήρυξης ΑΔΑ ΨΡΘ97ΛΛ-ΕΕΚ.
A3: Αντίγραφο ανά πελάτη και πρόσκληση, σε χώρο με αποθήκευση στην ΕΕ, σύμβαση επεξεργασίας (DPA), MFA και χωρίς δημόσιους συνδέσμους. Όνομα αρχείου: κωδικός πελάτη και πρόσκληση, π.χ. Π01-πρόσκληση-3. Ποτέ στο git.
A4: Κίτρινα κελιά: τα συμπληρώνεις. Γκρι: υπολογίζονται. Τα φύλλα Πρόσκληση, Δρομολόγια, Πλέγμα και Προσφορά είναι κλειδωμένα χωρίς κωδικό, για να μη σβηστεί τύπος κατά λάθος.
A5: Σειρά: Πρόσκληση → Δρομολόγια (go/no-go και απόφαση του πελάτη) → Προσφορά (έλεγχος πριν την υποβολή) → Έγγραφα (φάκελος, προσωρινός ανάδοχος, σύμβαση).
A6: Κενό κελί δεν είναι μηδέν. Όσο λείπει στοιχείο, τα αποτελέσματα γράφουν «λείπουν στοιχεία» ή UNKNOWN, και το UNKNOWN μετράει σαν NOT_SATISFIED.
A7: Ο πίνακας δείχνει αριθμούς. Την έκπτωση την αποφασίζει ο πελάτης. Εμείς δεν πληκτρολογούμε ποτέ στο ΕΣΗΔΗΣ και δεν ζητάμε κωδικούς.
A8: Ποτέ σε αυτό το αρχείο: ονόματα, ΑΦΜ, πινακίδες, κωδικοί πρόσβασης, αρχεία ή περιεχόμενο εγγράφων, στοιχεία υγείας ή ποινικού μητρώου. Μόνο κωδικός πελάτη, ποσά, ημερομηνίες και καταστάσεις.
A9: Οι ημερομηνίες μετράνε αυστηρά (docs/architecture.md AD8): οι εργάσιμες μετράνε χωρίς αργίες και οι ισχύς ζητούνται λίγο μεγαλύτερες, άρα το φύλλο προειδοποιεί νωρίτερα, ποτέ αργότερα.
A10: Πρότυπο της 24/09/2026. Αν μια πρόσκληση λέει κάτι άλλο από τη διακήρυξη, ισχύει η πρόσκληση: έλεγξε το φύλλο σε κάθε κύκλο.

Sheet Πρόσκληση
A1: Πρόσκληση και κόστη του πελάτη
A2: Κίτρινα: τα συμπληρώνεις. Γκρι: υπολογίζονται ή είναι σταθερές της διακήρυξης.
A3: Στοιχείο | B3: Τιμή | C3: Πηγή ή σημείωση
A4: Κωδικός πελάτη | C4: Π01, Π02, … Το κλειδί κωδικός → όνομα φυλάσσεται χωριστά
A5: Πρόσκληση (αριθμός ή ΑΔΑΜ)
A6: Ημερομηνία πρόσκλησης | C6: Οι υπεύθυνες δηλώσεις υπογράφονται μετά από αυτήν (§4.3.1.1)
A7: Προθεσμία υποβολής προσφορών | C7: Από την πρόσκληση
A8: Αποσφράγιση | C8: Ως τότε φτάνει το πρωτότυπο της έντυπης εγγύησης (§4.3.1.2)
A9: Σχολικά έτη της σύμβασης | C9: Από την πρόσκληση, π.χ. 3 για 2026–27 έως 2028–29
A10: Υπογραφή σύμβασης (εκτίμηση) | C10: Για τους μήνες της εγγύησης καλής εκτέλεσης
A11: Λήξη σύμβασης | C11: Από την πρόσκληση (§7.2.1)
A12: Υποβολή δικαιολογητικών προσωρινού αναδόχου | C12: Μέσα σε 10 ημέρες από την ειδοποίηση (§5.3.1). Πριν έρθει, βάλε εκτίμηση για προέλεγχο
A13: Υπόδειγμα οικονομικής προσφοράς | C13: Παράρτημα ΙΙΙ της διακήρυξης (§4.3.2.1)· στις δύο προσκλήσεις Ε.Δ.Χ. του 2026 ήταν το Παράρτημα ΙΙ
A15: Υπολογίζονται
A16: Η προσφορά ισχύει τουλάχιστον ως | B16: =IF(ISNUMBER(deadline),EDATE(deadline+1,12),"") | C16: 12 μήνες από την επομένη της προθεσμίας (§4.4.1), αυστηρή ανάγνωση
A17: Εγγύηση συμμετοχής: ισχύς τουλάχιστον ως | B17: =IF(ISNUMBER(B16),B16+30,"") | C17: 30 ημέρες μετά την ισχύ της προσφοράς (§4.3.1.2)
A18: Εγγύηση καλής εκτέλεσης: ισχύς τουλάχιστον ως | B18: =IF(ISNUMBER(contract_end),EDATE(contract_end,2),"") | C18: 2 μήνες μετά τη λήξη της σύμβασης (§6.2.1)
A19: Μήνες εγγύησης καλής εκτέλεσης | B19: =IF(AND(ISNUMBER(sign_date),ISNUMBER(contract_end)),YEARFRAC(sign_date,contract_end)*12+2,"") | C19: Από την υπογραφή ως 2 μήνες μετά τη λήξη
A21: Κόστη του πελάτη (τα δίνει ο πελάτης)
A22: Κατανάλωση (λίτρα ανά 100 χλμ)
A23: Τιμή καυσίμου (€ ανά λίτρο) | C23: Όπως σου κοστίζει. Αν συμψηφίζεις ΦΠΑ, χωρίς ΦΠΑ: ρώτα τον λογιστή
A24: Φθορές: λάστιχα, service, απόσβεση (€ ανά χλμ)
A25: Τι βγάζεις από κούρσες στις ώρες των δρομολογίων, μετά το καύσιμο (€ ανά ώρα) | C25: Όσα χάνεις όσο κάνεις το δρομολόγιο (plan §5, ευκαιρία)
A26: Επιπλέον ασφάλιστρο για τους μαθητές (€ τον χρόνο) | C26: 0 αν το συμβόλαιο ήδη καλύπτει επιβαίνοντες για όλη τη σύμβαση (§7.6, όροι 14–15)
A27: Προμήθεια τράπεζας για εγγυητικές (% τον χρόνο) | C27: Ρώτα την τράπεζα
A28: Έξοδα έκδοσης ανά εγγυητική (€) | C28: Ρώτα την τράπεζα
A29: Ημέρες που περιμένεις να πληρωθείς (% των ημερών του Παραρτήματος Ι) | C29: Δεν πληρώνονται μέρες χωρίς σχολείο, απεργίες, καταλήψεις, κλειστά σχολεία λόγω κακοκαιρίας, απουσία μαθητή λόγω ασθένειας (§6.6.3)
A30: Σενάριο: αύξηση τιμής καυσίμου (%) | C30: Για τα ταξί δεν υπάρχει αναπροσαρμογή για το καύσιμο (§6.6.4)
A32: Σταθερές της διακήρυξης
A33: Κρατήσεις υπέρ τρίτων | B33: 0.0012 | C33: 0,1% ΕΑΑΔΗΣΥ + 0,02% ΟΠΣ ΕΣΗΔΗΣ, σε κάθε πληρωμή (§6.6.2)
A34: Κρατήσεις μαζί με χαρτόσημο και ΟΓΑ | B34: =B33*(1+0.03*1.2) | C34: Χαρτόσημο 3% στις κρατήσεις και ΟΓΑ 20% στο χαρτόσημο (§4.3.2.2, §6.6.2)
A35: Εγγύηση συμμετοχής | B35: 0.002 | C35: Του προϋπολογισμού χωρίς ΦΠΑ και προαίρεση (§4.3.1.2)
A36: Εγγύηση καλής εκτέλεσης | B36: 0.04 | C36: Της αξίας της σύμβασης χωρίς προαίρεση (§6.2.1)
A37: Μήνες που μένει η εγγύηση συμμετοχής | B37: 13 | C37: Υπόθεση: όλη η ισχύς, 12 μήνες η προσφορά και 30 ημέρες (§4.4.1, §4.3.1.2)
A39: Όλα τα κόστη και οι ημερομηνίες της σύμβασης συμπληρωμένα; | B39: =AND(ISNUMBER(years),years>0,ISNUMBER(sign_date),ISNUMBER(contract_end),contract_end>sign_date,ISNUMBER(fuel_cons),ISNUMBER(fuel_price),ISNUMBER(wear),ISNUMBER(opp_rate),ISNUMBER(ins_year),ISNUMBER(bank_rate),ISNUMBER(bank_fee),ISNUMBER(paid_share),paid_share>0,paid_share<=1,ISNUMBER(fuel_scn)) | C39: Αν όχι, τα Δρομολόγια γράφουν «λείπουν στοιχεία»

Sheet Δρομολόγια
A1: Δρομολόγια: go/no-go ανά δρομολόγιο
A2: Ο πίνακας δείχνει αριθμούς. Την έκπτωση την αποφασίζει ο πελάτης. Καθαρό = πριν τον φόρο εισοδήματος· σε κάθε πληρωμή γίνεται παρακράτηση φόρου (§6.6.2): ρώτα τον λογιστή.
A3: Πες τα στον πελάτη: καμία αναπροσαρμογή για το καύσιμο (§6.6.4) · κατάργηση ή συγχώνευση δρομολογίου χωρίς αποζημίωση (§7.6.1) και αλλαγές στη διαδρομή που πρέπει να δεχτεί (§7.6.2–3) · δεν πληρώνονται μέρες χωρίς μεταφορά (§6.6.3) · τον συνοδό τον πληρώνει ο ανάδοχος, η δαπάνη του είναι μέσα στην τιμή (§4.3.2.2) · εφεδρικό όχημα, αλλιώς πληρώνει άλλο μέσο (§7.6.5) · η έκπτωση δεσμεύει ως τη λήξη (§4.3.2.1) · η εγγύηση 4% μένει ως 2 μήνες μετά τη λήξη (§6.2.1) · πολύ μεγάλη έκπτωση μπορεί να κριθεί ασυνήθιστα χαμηλή και να ζητηθούν εξηγήσεις σε ≤20 ημέρες (§5.2.2).
B4: Από το Παράρτημα Ι της πρόσκλησης | J4: Εκτίμηση του πελάτη | M4: Απόφαση του πελάτη | P4: Αποτελέσματα (δεν αλλάζουν)
A5: # | B5: Α/Α Παραρτήματος Ι | C5: Κωδικός δρομολογίου | D5: Ομάδα (αν υπάρχει) | E5: Συνοδός (ΝΑΙ/ΟΧΙ) | F5: Τιμή αναφοράς (€/ημέρα, χωρίς ΦΠΑ) | G5: Ημέρες (Παράρτημα Ι) | H5: Προϋπολογισμός χωρίς ΦΠΑ και προαίρεση (€) | I5: Άγονο σε προηγούμενη πρόσκληση | J5: Χιλιόμετρα την ημέρα, όλα (με μαθητές και άδεια) | K5: Ώρες την ημέρα που δεσμεύει | L5: Συνοδός (€/ημέρα) | M5: Έκπτωση που εξετάζει ο πελάτης (%) | N5: Απόφαση πελάτη (ΝΑΙ/ΟΧΙ) | O5: Ημερομηνία απόφασης | P5: Πλήρη στοιχεία | Q5: Ημέρες πληρωμής τον χρόνο | R5: Σταθερό κόστος (€/ημέρα) | S5: Κρατήσεις και εγγύηση 4% (επί της τιμής) | T5: Καθαρό με 0% (€/ημέρα) | U5: Καθαρό με 0% (€/έτος) | V5: Όριο έκπτωσης (%): η μεγαλύτερη με καθαρό ≥ 0 | W5: Καθαρό στην έκπτωση που εξετάζει (€/ημέρα) | X5: Καθαρό στην έκπτωση που εξετάζει (€/έτος) | Y5: Καθαρό με το σενάριο καυσίμου (€/ημέρα, στην έκπτωση που εξετάζει, αλλιώς 0%) | Z5: Εγγύηση συμμετοχής (€, 0,2%) | AA5: Εγγύηση καλής εκτέλεσης (€, 4%, στην έκπτωση που εξετάζει, αλλιώς 0%) | AB5: Προσοχή
A6: 1 | P6: =AND(inputs_ok,C6<>"",OR(E6="ΝΑΙ",E6="ΟΧΙ"),ISNUMBER(F6),F6>0,ISNUMBER(G6),G6>0,ISNUMBER(H6),ISNUMBER(J6),ISNUMBER(K6),OR(E6="ΟΧΙ",ISNUMBER(L6))) | Q6: =IF(P6,G6/years*paid_share,"") | R6: =IF(P6,J6*(fuel_cons/100*fuel_price+wear)+IF(E6="ΝΑΙ",L6,0)+ins_year/Q6+K6*opp_rate+(2*bank_fee+bank_rate*Z6*gp_months/12)/(G6*paid_share),"") | S6: =IF(P6,ded_rate+gg_rate*bank_rate*gg_months/12/paid_share,"") | T6: =IF(P6,'Πλέγμα'!B6,"λείπουν στοιχεία") | U6: =IF(P6,T6*Q6,"") | V6: =IF(NOT(P6),"λείπουν στοιχεία",IF(T6<0,"καμία: ζημιά και με 0%",_xlfn.MAXIFS('Πλέγμα'!$A$6:$A$105,'Πλέγμα'!B$6:B$105,">=0"))) | W6: =IF(OR(NOT(P6),M6=""),"",IF(AND(ISNUMBER(M6),M6=INT(M6),M6>=0,M6<=99),INDEX('Πλέγμα'!B$6:B$105,M6+1),"ακέραια έκπτωση 0–99")) | X6: =IF(ISNUMBER(W6),W6*Q6,"") | Y6: =IF(NOT(P6),"",IF(ISNUMBER(W6),W6,T6)-J6*fuel_cons/100*fuel_price*fuel_scn) | Z6: =IF(ISNUMBER(H6),ROUNDUP(ROUND(ROUND(H6*100,0)*gp_rate,6),0)/100,"") | AA6: =IF(AND(ISNUMBER(F6),ISNUMBER(G6)),ROUNDUP(ROUND(ROUND(ROUND(F6*100,0)*(100-IF(AND(ISNUMBER(M6),M6=INT(M6),M6>=0,M6<=99),M6,0))/100,0)*G6*gg_rate,6),0)/100,"") | AB6: =IF(C6="","",TRIM(IF(AND(E6="ΝΑΙ",ISNUMBER(L6)),IF(L6=0,"Συνοδός με 0 €; Τον πληρώνει ο ανάδοχος (§4.3.2.2). ",""),"")&IF(ISNUMBER(T6),IF(T6<0,"Ζημιά και με 0%. ",""),"")&IF(AND(N6="ΝΑΙ",NOT(ISNUMBER(O6))),"Λείπει η ημερομηνία απόφασης. ","")))
A7: 2 | P7: =AND(inputs_ok,C7<>"",OR(E7="ΝΑΙ",E7="ΟΧΙ"),ISNUMBER(F7),F7>0,ISNUMBER(G7),G7>0,ISNUMBER(H7),ISNUMBER(J7),ISNUMBER(K7),OR(E7="ΟΧΙ",ISNUMBER(L7))) | Q7: =IF(P7,G7/years*paid_share,"") | R7: =IF(P7,J7*(fuel_cons/100*fuel_price+wear)+IF(E7="ΝΑΙ",L7,0)+ins_year/Q7+K7*opp_rate+(2*bank_fee+bank_rate*Z7*gp_months/12)/(G7*paid_share),"") | S7: =IF(P7,ded_rate+gg_rate*bank_rate*gg_months/12/paid_share,"") | T7: =IF(P7,'Πλέγμα'!C6,"λείπουν στοιχεία") | U7: =IF(P7,T7*Q7,"") | V7: =IF(NOT(P7),"λείπουν στοιχεία",IF(T7<0,"καμία: ζημιά και με 0%",_xlfn.MAXIFS('Πλέγμα'!$A$6:$A$105,'Πλέγμα'!C$6:C$105,">=0"))) | W7: =IF(OR(NOT(P7),M7=""),"",IF(AND(ISNUMBER(M7),M7=INT(M7),M7>=0,M7<=99),INDEX('Πλέγμα'!C$6:C$105,M7+1),"ακέραια έκπτωση 0–99")) | X7: =IF(ISNUMBER(W7),W7*Q7,"") | Y7: =IF(NOT(P7),"",IF(ISNUMBER(W7),W7,T7)-J7*fuel_cons/100*fuel_price*fuel_scn) | Z7: =IF(ISNUMBER(H7),ROUNDUP(ROUND(ROUND(H7*100,0)*gp_rate,6),0)/100,"") | AA7: =IF(AND(ISNUMBER(F7),ISNUMBER(G7)),ROUNDUP(ROUND(ROUND(ROUND(F7*100,0)*(100-IF(AND(ISNUMBER(M7),M7=INT(M7),M7>=0,M7<=99),M7,0))/100,0)*G7*gg_rate,6),0)/100,"") | AB7: =IF(C7="","",TRIM(IF(AND(E7="ΝΑΙ",ISNUMBER(L7)),IF(L7=0,"Συνοδός με 0 €; Τον πληρώνει ο ανάδοχος (§4.3.2.2). ",""),"")&IF(ISNUMBER(T7),IF(T7<0,"Ζημιά και με 0%. ",""),"")&IF(AND(N7="ΝΑΙ",NOT(ISNUMBER(O7))),"Λείπει η ημερομηνία απόφασης. ","")))
A8: 3 | P8: =AND(inputs_ok,C8<>"",OR(E8="ΝΑΙ",E8="ΟΧΙ"),ISNUMBER(F8),F8>0,ISNUMBER(G8),G8>0,ISNUMBER(H8),ISNUMBER(J8),ISNUMBER(K8),OR(E8="ΟΧΙ",ISNUMBER(L8))) | Q8: =IF(P8,G8/years*paid_share,"") | R8: =IF(P8,J8*(fuel_cons/100*fuel_price+wear)+IF(E8="ΝΑΙ",L8,0)+ins_year/Q8+K8*opp_rate+(2*bank_fee+bank_rate*Z8*gp_months/12)/(G8*paid_share),"") | S8: =IF(P8,ded_rate+gg_rate*bank_rate*gg_months/12/paid_share,"") | T8: =IF(P8,'Πλέγμα'!D6,"λείπουν στοιχεία") | U8: =IF(P8,T8*Q8,"") | V8: =IF(NOT(P8),"λείπουν στοιχεία",IF(T8<0,"καμία: ζημιά και με 0%",_xlfn.MAXIFS('Πλέγμα'!$A$6:$A$105,'Πλέγμα'!D$6:D$105,">=0"))) | W8: =IF(OR(NOT(P8),M8=""),"",IF(AND(ISNUMBER(M8),M8=INT(M8),M8>=0,M8<=99),INDEX('Πλέγμα'!D$6:D$105,M8+1),"ακέραια έκπτωση 0–99")) | X8: =IF(ISNUMBER(W8),W8*Q8,"") | Y8: =IF(NOT(P8),"",IF(ISNUMBER(W8),W8,T8)-J8*fuel_cons/100*fuel_price*fuel_scn) | Z8: =IF(ISNUMBER(H8),ROUNDUP(ROUND(ROUND(H8*100,0)*gp_rate,6),0)/100,"") | AA8: =IF(AND(ISNUMBER(F8),ISNUMBER(G8)),ROUNDUP(ROUND(ROUND(ROUND(F8*100,0)*(100-IF(AND(ISNUMBER(M8),M8=INT(M8),M8>=0,M8<=99),M8,0))/100,0)*G8*gg_rate,6),0)/100,"") | AB8: =IF(C8="","",TRIM(IF(AND(E8="ΝΑΙ",ISNUMBER(L8)),IF(L8=0,"Συνοδός με 0 €; Τον πληρώνει ο ανάδοχος (§4.3.2.2). ",""),"")&IF(ISNUMBER(T8),IF(T8<0,"Ζημιά και με 0%. ",""),"")&IF(AND(N8="ΝΑΙ",NOT(ISNUMBER(O8))),"Λείπει η ημερομηνία απόφασης. ","")))
A9: 4 | P9: =AND(inputs_ok,C9<>"",OR(E9="ΝΑΙ",E9="ΟΧΙ"),ISNUMBER(F9),F9>0,ISNUMBER(G9),G9>0,ISNUMBER(H9),ISNUMBER(J9),ISNUMBER(K9),OR(E9="ΟΧΙ",ISNUMBER(L9))) | Q9: =IF(P9,G9/years*paid_share,"") | R9: =IF(P9,J9*(fuel_cons/100*fuel_price+wear)+IF(E9="ΝΑΙ",L9,0)+ins_year/Q9+K9*opp_rate+(2*bank_fee+bank_rate*Z9*gp_months/12)/(G9*paid_share),"") | S9: =IF(P9,ded_rate+gg_rate*bank_rate*gg_months/12/paid_share,"") | T9: =IF(P9,'Πλέγμα'!E6,"λείπουν στοιχεία") | U9: =IF(P9,T9*Q9,"") | V9: =IF(NOT(P9),"λείπουν στοιχεία",IF(T9<0,"καμία: ζημιά και με 0%",_xlfn.MAXIFS('Πλέγμα'!$A$6:$A$105,'Πλέγμα'!E$6:E$105,">=0"))) | W9: =IF(OR(NOT(P9),M9=""),"",IF(AND(ISNUMBER(M9),M9=INT(M9),M9>=0,M9<=99),INDEX('Πλέγμα'!E$6:E$105,M9+1),"ακέραια έκπτωση 0–99")) | X9: =IF(ISNUMBER(W9),W9*Q9,"") | Y9: =IF(NOT(P9),"",IF(ISNUMBER(W9),W9,T9)-J9*fuel_cons/100*fuel_price*fuel_scn) | Z9: =IF(ISNUMBER(H9),ROUNDUP(ROUND(ROUND(H9*100,0)*gp_rate,6),0)/100,"") | AA9: =IF(AND(ISNUMBER(F9),ISNUMBER(G9)),ROUNDUP(ROUND(ROUND(ROUND(F9*100,0)*(100-IF(AND(ISNUMBER(M9),M9=INT(M9),M9>=0,M9<=99),M9,0))/100,0)*G9*gg_rate,6),0)/100,"") | AB9: =IF(C9="","",TRIM(IF(AND(E9="ΝΑΙ",ISNUMBER(L9)),IF(L9=0,"Συνοδός με 0 €; Τον πληρώνει ο ανάδοχος (§4.3.2.2). ",""),"")&IF(ISNUMBER(T9),IF(T9<0,"Ζημιά και με 0%. ",""),"")&IF(AND(N9="ΝΑΙ",NOT(ISNUMBER(O9))),"Λείπει η ημερομηνία απόφασης. ","")))
A10: 5 | P10: =AND(inputs_ok,C10<>"",OR(E10="ΝΑΙ",E10="ΟΧΙ"),ISNUMBER(F10),F10>0,ISNUMBER(G10),G10>0,ISNUMBER(H10),ISNUMBER(J10),ISNUMBER(K10),OR(E10="ΟΧΙ",ISNUMBER(L10))) | Q10: =IF(P10,G10/years*paid_share,"") | R10: =IF(P10,J10*(fuel_cons/100*fuel_price+wear)+IF(E10="ΝΑΙ",L10,0)+ins_year/Q10+K10*opp_rate+(2*bank_fee+bank_rate*Z10*gp_months/12)/(G10*paid_share),"") | S10: =IF(P10,ded_rate+gg_rate*bank_rate*gg_months/12/paid_share,"") | T10: =IF(P10,'Πλέγμα'!F6,"λείπουν στοιχεία") | U10: =IF(P10,T10*Q10,"") | V10: =IF(NOT(P10),"λείπουν στοιχεία",IF(T10<0,"καμία: ζημιά και με 0%",_xlfn.MAXIFS('Πλέγμα'!$A$6:$A$105,'Πλέγμα'!F$6:F$105,">=0"))) | W10: =IF(OR(NOT(P10),M10=""),"",IF(AND(ISNUMBER(M10),M10=INT(M10),M10>=0,M10<=99),INDEX('Πλέγμα'!F$6:F$105,M10+1),"ακέραια έκπτωση 0–99")) | X10: =IF(ISNUMBER(W10),W10*Q10,"") | Y10: =IF(NOT(P10),"",IF(ISNUMBER(W10),W10,T10)-J10*fuel_cons/100*fuel_price*fuel_scn) | Z10: =IF(ISNUMBER(H10),ROUNDUP(ROUND(ROUND(H10*100,0)*gp_rate,6),0)/100,"") | AA10: =IF(AND(ISNUMBER(F10),ISNUMBER(G10)),ROUNDUP(ROUND(ROUND(ROUND(F10*100,0)*(100-IF(AND(ISNUMBER(M10),M10=INT(M10),M10>=0,M10<=99),M10,0))/100,0)*G10*gg_rate,6),0)/100,"") | AB10: =IF(C10="","",TRIM(IF(AND(E10="ΝΑΙ",ISNUMBER(L10)),IF(L10=0,"Συνοδός με 0 €; Τον πληρώνει ο ανάδοχος (§4.3.2.2). ",""),"")&IF(ISNUMBER(T10),IF(T10<0,"Ζημιά και με 0%. ",""),"")&IF(AND(N10="ΝΑΙ",NOT(ISNUMBER(O10))),"Λείπει η ημερομηνία απόφασης. ","")))
A11: 6 | P11: =AND(inputs_ok,C11<>"",OR(E11="ΝΑΙ",E11="ΟΧΙ"),ISNUMBER(F11),F11>0,ISNUMBER(G11),G11>0,ISNUMBER(H11),ISNUMBER(J11),ISNUMBER(K11),OR(E11="ΟΧΙ",ISNUMBER(L11))) | Q11: =IF(P11,G11/years*paid_share,"") | R11: =IF(P11,J11*(fuel_cons/100*fuel_price+wear)+IF(E11="ΝΑΙ",L11,0)+ins_year/Q11+K11*opp_rate+(2*bank_fee+bank_rate*Z11*gp_months/12)/(G11*paid_share),"") | S11: =IF(P11,ded_rate+gg_rate*bank_rate*gg_months/12/paid_share,"") | T11: =IF(P11,'Πλέγμα'!G6,"λείπουν στοιχεία") | U11: =IF(P11,T11*Q11,"") | V11: =IF(NOT(P11),"λείπουν στοιχεία",IF(T11<0,"καμία: ζημιά και με 0%",_xlfn.MAXIFS('Πλέγμα'!$A$6:$A$105,'Πλέγμα'!G$6:G$105,">=0"))) | W11: =IF(OR(NOT(P11),M11=""),"",IF(AND(ISNUMBER(M11),M11=INT(M11),M11>=0,M11<=99),INDEX('Πλέγμα'!G$6:G$105,M11+1),"ακέραια έκπτωση 0–99")) | X11: =IF(ISNUMBER(W11),W11*Q11,"") | Y11: =IF(NOT(P11),"",IF(ISNUMBER(W11),W11,T11)-J11*fuel_cons/100*fuel_price*fuel_scn) | Z11: =IF(ISNUMBER(H11),ROUNDUP(ROUND(ROUND(H11*100,0)*gp_rate,6),0)/100,"") | AA11: =IF(AND(ISNUMBER(F11),ISNUMBER(G11)),ROUNDUP(ROUND(ROUND(ROUND(F11*100,0)*(100-IF(AND(ISNUMBER(M11),M11=INT(M11),M11>=0,M11<=99),M11,0))/100,0)*G11*gg_rate,6),0)/100,"") | AB11: =IF(C11="","",TRIM(IF(AND(E11="ΝΑΙ",ISNUMBER(L11)),IF(L11=0,"Συνοδός με 0 €; Τον πληρώνει ο ανάδοχος (§4.3.2.2). ",""),"")&IF(ISNUMBER(T11),IF(T11<0,"Ζημιά και με 0%. ",""),"")&IF(AND(N11="ΝΑΙ",NOT(ISNUMBER(O11))),"Λείπει η ημερομηνία απόφασης. ","")))
A12: 7 | P12: =AND(inputs_ok,C12<>"",OR(E12="ΝΑΙ",E12="ΟΧΙ"),ISNUMBER(F12),F12>0,ISNUMBER(G12),G12>0,ISNUMBER(H12),ISNUMBER(J12),ISNUMBER(K12),OR(E12="ΟΧΙ",ISNUMBER(L12))) | Q12: =IF(P12,G12/years*paid_share,"") | R12: =IF(P12,J12*(fuel_cons/100*fuel_price+wear)+IF(E12="ΝΑΙ",L12,0)+ins_year/Q12+K12*opp_rate+(2*bank_fee+bank_rate*Z12*gp_months/12)/(G12*paid_share),"") | S12: =IF(P12,ded_rate+gg_rate*bank_rate*gg_months/12/paid_share,"") | T12: =IF(P12,'Πλέγμα'!H6,"λείπουν στοιχεία") | U12: =IF(P12,T12*Q12,"") | V12: =IF(NOT(P12),"λείπουν στοιχεία",IF(T12<0,"καμία: ζημιά και με 0%",_xlfn.MAXIFS('Πλέγμα'!$A$6:$A$105,'Πλέγμα'!H$6:H$105,">=0"))) | W12: =IF(OR(NOT(P12),M12=""),"",IF(AND(ISNUMBER(M12),M12=INT(M12),M12>=0,M12<=99),INDEX('Πλέγμα'!H$6:H$105,M12+1),"ακέραια έκπτωση 0–99")) | X12: =IF(ISNUMBER(W12),W12*Q12,"") | Y12: =IF(NOT(P12),"",IF(ISNUMBER(W12),W12,T12)-J12*fuel_cons/100*fuel_price*fuel_scn) | Z12: =IF(ISNUMBER(H12),ROUNDUP(ROUND(ROUND(H12*100,0)*gp_rate,6),0)/100,"") | AA12: =IF(AND(ISNUMBER(F12),ISNUMBER(G12)),ROUNDUP(ROUND(ROUND(ROUND(F12*100,0)*(100-IF(AND(ISNUMBER(M12),M12=INT(M12),M12>=0,M12<=99),M12,0))/100,0)*G12*gg_rate,6),0)/100,"") | AB12: =IF(C12="","",TRIM(IF(AND(E12="ΝΑΙ",ISNUMBER(L12)),IF(L12=0,"Συνοδός με 0 €; Τον πληρώνει ο ανάδοχος (§4.3.2.2). ",""),"")&IF(ISNUMBER(T12),IF(T12<0,"Ζημιά και με 0%. ",""),"")&IF(AND(N12="ΝΑΙ",NOT(ISNUMBER(O12))),"Λείπει η ημερομηνία απόφασης. ","")))
A13: 8 | P13: =AND(inputs_ok,C13<>"",OR(E13="ΝΑΙ",E13="ΟΧΙ"),ISNUMBER(F13),F13>0,ISNUMBER(G13),G13>0,ISNUMBER(H13),ISNUMBER(J13),ISNUMBER(K13),OR(E13="ΟΧΙ",ISNUMBER(L13))) | Q13: =IF(P13,G13/years*paid_share,"") | R13: =IF(P13,J13*(fuel_cons/100*fuel_price+wear)+IF(E13="ΝΑΙ",L13,0)+ins_year/Q13+K13*opp_rate+(2*bank_fee+bank_rate*Z13*gp_months/12)/(G13*paid_share),"") | S13: =IF(P13,ded_rate+gg_rate*bank_rate*gg_months/12/paid_share,"") | T13: =IF(P13,'Πλέγμα'!I6,"λείπουν στοιχεία") | U13: =IF(P13,T13*Q13,"") | V13: =IF(NOT(P13),"λείπουν στοιχεία",IF(T13<0,"καμία: ζημιά και με 0%",_xlfn.MAXIFS('Πλέγμα'!$A$6:$A$105,'Πλέγμα'!I$6:I$105,">=0"))) | W13: =IF(OR(NOT(P13),M13=""),"",IF(AND(ISNUMBER(M13),M13=INT(M13),M13>=0,M13<=99),INDEX('Πλέγμα'!I$6:I$105,M13+1),"ακέραια έκπτωση 0–99")) | X13: =IF(ISNUMBER(W13),W13*Q13,"") | Y13: =IF(NOT(P13),"",IF(ISNUMBER(W13),W13,T13)-J13*fuel_cons/100*fuel_price*fuel_scn) | Z13: =IF(ISNUMBER(H13),ROUNDUP(ROUND(ROUND(H13*100,0)*gp_rate,6),0)/100,"") | AA13: =IF(AND(ISNUMBER(F13),ISNUMBER(G13)),ROUNDUP(ROUND(ROUND(ROUND(F13*100,0)*(100-IF(AND(ISNUMBER(M13),M13=INT(M13),M13>=0,M13<=99),M13,0))/100,0)*G13*gg_rate,6),0)/100,"") | AB13: =IF(C13="","",TRIM(IF(AND(E13="ΝΑΙ",ISNUMBER(L13)),IF(L13=0,"Συνοδός με 0 €; Τον πληρώνει ο ανάδοχος (§4.3.2.2). ",""),"")&IF(ISNUMBER(T13),IF(T13<0,"Ζημιά και με 0%. ",""),"")&IF(AND(N13="ΝΑΙ",NOT(ISNUMBER(O13))),"Λείπει η ημερομηνία απόφασης. ","")))
A14: 9 | P14: =AND(inputs_ok,C14<>"",OR(E14="ΝΑΙ",E14="ΟΧΙ"),ISNUMBER(F14),F14>0,ISNUMBER(G14),G14>0,ISNUMBER(H14),ISNUMBER(J14),ISNUMBER(K14),OR(E14="ΟΧΙ",ISNUMBER(L14))) | Q14: =IF(P14,G14/years*paid_share,"") | R14: =IF(P14,J14*(fuel_cons/100*fuel_price+wear)+IF(E14="ΝΑΙ",L14,0)+ins_year/Q14+K14*opp_rate+(2*bank_fee+bank_rate*Z14*gp_months/12)/(G14*paid_share),"") | S14: =IF(P14,ded_rate+gg_rate*bank_rate*gg_months/12/paid_share,"") | T14: =IF(P14,'Πλέγμα'!J6,"λείπουν στοιχεία") | U14: =IF(P14,T14*Q14,"") | V14: =IF(NOT(P14),"λείπουν στοιχεία",IF(T14<0,"καμία: ζημιά και με 0%",_xlfn.MAXIFS('Πλέγμα'!$A$6:$A$105,'Πλέγμα'!J$6:J$105,">=0"))) | W14: =IF(OR(NOT(P14),M14=""),"",IF(AND(ISNUMBER(M14),M14=INT(M14),M14>=0,M14<=99),INDEX('Πλέγμα'!J$6:J$105,M14+1),"ακέραια έκπτωση 0–99")) | X14: =IF(ISNUMBER(W14),W14*Q14,"") | Y14: =IF(NOT(P14),"",IF(ISNUMBER(W14),W14,T14)-J14*fuel_cons/100*fuel_price*fuel_scn) | Z14: =IF(ISNUMBER(H14),ROUNDUP(ROUND(ROUND(H14*100,0)*gp_rate,6),0)/100,"") | AA14: =IF(AND(ISNUMBER(F14),ISNUMBER(G14)),ROUNDUP(ROUND(ROUND(ROUND(F14*100,0)*(100-IF(AND(ISNUMBER(M14),M14=INT(M14),M14>=0,M14<=99),M14,0))/100,0)*G14*gg_rate,6),0)/100,"") | AB14: =IF(C14="","",TRIM(IF(AND(E14="ΝΑΙ",ISNUMBER(L14)),IF(L14=0,"Συνοδός με 0 €; Τον πληρώνει ο ανάδοχος (§4.3.2.2). ",""),"")&IF(ISNUMBER(T14),IF(T14<0,"Ζημιά και με 0%. ",""),"")&IF(AND(N14="ΝΑΙ",NOT(ISNUMBER(O14))),"Λείπει η ημερομηνία απόφασης. ","")))
A15: 10 | P15: =AND(inputs_ok,C15<>"",OR(E15="ΝΑΙ",E15="ΟΧΙ"),ISNUMBER(F15),F15>0,ISNUMBER(G15),G15>0,ISNUMBER(H15),ISNUMBER(J15),ISNUMBER(K15),OR(E15="ΟΧΙ",ISNUMBER(L15))) | Q15: =IF(P15,G15/years*paid_share,"") | R15: =IF(P15,J15*(fuel_cons/100*fuel_price+wear)+IF(E15="ΝΑΙ",L15,0)+ins_year/Q15+K15*opp_rate+(2*bank_fee+bank_rate*Z15*gp_months/12)/(G15*paid_share),"") | S15: =IF(P15,ded_rate+gg_rate*bank_rate*gg_months/12/paid_share,"") | T15: =IF(P15,'Πλέγμα'!K6,"λείπουν στοιχεία") | U15: =IF(P15,T15*Q15,"") | V15: =IF(NOT(P15),"λείπουν στοιχεία",IF(T15<0,"καμία: ζημιά και με 0%",_xlfn.MAXIFS('Πλέγμα'!$A$6:$A$105,'Πλέγμα'!K$6:K$105,">=0"))) | W15: =IF(OR(NOT(P15),M15=""),"",IF(AND(ISNUMBER(M15),M15=INT(M15),M15>=0,M15<=99),INDEX('Πλέγμα'!K$6:K$105,M15+1),"ακέραια έκπτωση 0–99")) | X15: =IF(ISNUMBER(W15),W15*Q15,"") | Y15: =IF(NOT(P15),"",IF(ISNUMBER(W15),W15,T15)-J15*fuel_cons/100*fuel_price*fuel_scn) | Z15: =IF(ISNUMBER(H15),ROUNDUP(ROUND(ROUND(H15*100,0)*gp_rate,6),0)/100,"") | AA15: =IF(AND(ISNUMBER(F15),ISNUMBER(G15)),ROUNDUP(ROUND(ROUND(ROUND(F15*100,0)*(100-IF(AND(ISNUMBER(M15),M15=INT(M15),M15>=0,M15<=99),M15,0))/100,0)*G15*gg_rate,6),0)/100,"") | AB15: =IF(C15="","",TRIM(IF(AND(E15="ΝΑΙ",ISNUMBER(L15)),IF(L15=0,"Συνοδός με 0 €; Τον πληρώνει ο ανάδοχος (§4.3.2.2). ",""),"")&IF(ISNUMBER(T15),IF(T15<0,"Ζημιά και με 0%. ",""),"")&IF(AND(N15="ΝΑΙ",NOT(ISNUMBER(O15))),"Λείπει η ημερομηνία απόφασης. ","")))
A16: 11 | P16: =AND(inputs_ok,C16<>"",OR(E16="ΝΑΙ",E16="ΟΧΙ"),ISNUMBER(F16),F16>0,ISNUMBER(G16),G16>0,ISNUMBER(H16),ISNUMBER(J16),ISNUMBER(K16),OR(E16="ΟΧΙ",ISNUMBER(L16))) | Q16: =IF(P16,G16/years*paid_share,"") | R16: =IF(P16,J16*(fuel_cons/100*fuel_price+wear)+IF(E16="ΝΑΙ",L16,0)+ins_year/Q16+K16*opp_rate+(2*bank_fee+bank_rate*Z16*gp_months/12)/(G16*paid_share),"") | S16: =IF(P16,ded_rate+gg_rate*bank_rate*gg_months/12/paid_share,"") | T16: =IF(P16,'Πλέγμα'!L6,"λείπουν στοιχεία") | U16: =IF(P16,T16*Q16,"") | V16: =IF(NOT(P16),"λείπουν στοιχεία",IF(T16<0,"καμία: ζημιά και με 0%",_xlfn.MAXIFS('Πλέγμα'!$A$6:$A$105,'Πλέγμα'!L$6:L$105,">=0"))) | W16: =IF(OR(NOT(P16),M16=""),"",IF(AND(ISNUMBER(M16),M16=INT(M16),M16>=0,M16<=99),INDEX('Πλέγμα'!L$6:L$105,M16+1),"ακέραια έκπτωση 0–99")) | X16: =IF(ISNUMBER(W16),W16*Q16,"") | Y16: =IF(NOT(P16),"",IF(ISNUMBER(W16),W16,T16)-J16*fuel_cons/100*fuel_price*fuel_scn) | Z16: =IF(ISNUMBER(H16),ROUNDUP(ROUND(ROUND(H16*100,0)*gp_rate,6),0)/100,"") | AA16: =IF(AND(ISNUMBER(F16),ISNUMBER(G16)),ROUNDUP(ROUND(ROUND(ROUND(F16*100,0)*(100-IF(AND(ISNUMBER(M16),M16=INT(M16),M16>=0,M16<=99),M16,0))/100,0)*G16*gg_rate,6),0)/100,"") | AB16: =IF(C16="","",TRIM(IF(AND(E16="ΝΑΙ",ISNUMBER(L16)),IF(L16=0,"Συνοδός με 0 €; Τον πληρώνει ο ανάδοχος (§4.3.2.2). ",""),"")&IF(ISNUMBER(T16),IF(T16<0,"Ζημιά και με 0%. ",""),"")&IF(AND(N16="ΝΑΙ",NOT(ISNUMBER(O16))),"Λείπει η ημερομηνία απόφασης. ","")))
A17: 12 | P17: =AND(inputs_ok,C17<>"",OR(E17="ΝΑΙ",E17="ΟΧΙ"),ISNUMBER(F17),F17>0,ISNUMBER(G17),G17>0,ISNUMBER(H17),ISNUMBER(J17),ISNUMBER(K17),OR(E17="ΟΧΙ",ISNUMBER(L17))) | Q17: =IF(P17,G17/years*paid_share,"") | R17: =IF(P17,J17*(fuel_cons/100*fuel_price+wear)+IF(E17="ΝΑΙ",L17,0)+ins_year/Q17+K17*opp_rate+(2*bank_fee+bank_rate*Z17*gp_months/12)/(G17*paid_share),"") | S17: =IF(P17,ded_rate+gg_rate*bank_rate*gg_months/12/paid_share,"") | T17: =IF(P17,'Πλέγμα'!M6,"λείπουν στοιχεία") | U17: =IF(P17,T17*Q17,"") | V17: =IF(NOT(P17),"λείπουν στοιχεία",IF(T17<0,"καμία: ζημιά και με 0%",_xlfn.MAXIFS('Πλέγμα'!$A$6:$A$105,'Πλέγμα'!M$6:M$105,">=0"))) | W17: =IF(OR(NOT(P17),M17=""),"",IF(AND(ISNUMBER(M17),M17=INT(M17),M17>=0,M17<=99),INDEX('Πλέγμα'!M$6:M$105,M17+1),"ακέραια έκπτωση 0–99")) | X17: =IF(ISNUMBER(W17),W17*Q17,"") | Y17: =IF(NOT(P17),"",IF(ISNUMBER(W17),W17,T17)-J17*fuel_cons/100*fuel_price*fuel_scn) | Z17: =IF(ISNUMBER(H17),ROUNDUP(ROUND(ROUND(H17*100,0)*gp_rate,6),0)/100,"") | AA17: =IF(AND(ISNUMBER(F17),ISNUMBER(G17)),ROUNDUP(ROUND(ROUND(ROUND(F17*100,0)*(100-IF(AND(ISNUMBER(M17),M17=INT(M17),M17>=0,M17<=99),M17,0))/100,0)*G17*gg_rate,6),0)/100,"") | AB17: =IF(C17="","",TRIM(IF(AND(E17="ΝΑΙ",ISNUMBER(L17)),IF(L17=0,"Συνοδός με 0 €; Τον πληρώνει ο ανάδοχος (§4.3.2.2). ",""),"")&IF(ISNUMBER(T17),IF(T17<0,"Ζημιά και με 0%. ",""),"")&IF(AND(N17="ΝΑΙ",NOT(ISNUMBER(O17))),"Λείπει η ημερομηνία απόφασης. ","")))
A18: 13 | P18: =AND(inputs_ok,C18<>"",OR(E18="ΝΑΙ",E18="ΟΧΙ"),ISNUMBER(F18),F18>0,ISNUMBER(G18),G18>0,ISNUMBER(H18),ISNUMBER(J18),ISNUMBER(K18),OR(E18="ΟΧΙ",ISNUMBER(L18))) | Q18: =IF(P18,G18/years*paid_share,"") | R18: =IF(P18,J18*(fuel_cons/100*fuel_price+wear)+IF(E18="ΝΑΙ",L18,0)+ins_year/Q18+K18*opp_rate+(2*bank_fee+bank_rate*Z18*gp_months/12)/(G18*paid_share),"") | S18: =IF(P18,ded_rate+gg_rate*bank_rate*gg_months/12/paid_share,"") | T18: =IF(P18,'Πλέγμα'!N6,"λείπουν στοιχεία") | U18: =IF(P18,T18*Q18,"") | V18: =IF(NOT(P18),"λείπουν στοιχεία",IF(T18<0,"καμία: ζημιά και με 0%",_xlfn.MAXIFS('Πλέγμα'!$A$6:$A$105,'Πλέγμα'!N$6:N$105,">=0"))) | W18: =IF(OR(NOT(P18),M18=""),"",IF(AND(ISNUMBER(M18),M18=INT(M18),M18>=0,M18<=99),INDEX('Πλέγμα'!N$6:N$105,M18+1),"ακέραια έκπτωση 0–99")) | X18: =IF(ISNUMBER(W18),W18*Q18,"") | Y18: =IF(NOT(P18),"",IF(ISNUMBER(W18),W18,T18)-J18*fuel_cons/100*fuel_price*fuel_scn) | Z18: =IF(ISNUMBER(H18),ROUNDUP(ROUND(ROUND(H18*100,0)*gp_rate,6),0)/100,"") | AA18: =IF(AND(ISNUMBER(F18),ISNUMBER(G18)),ROUNDUP(ROUND(ROUND(ROUND(F18*100,0)*(100-IF(AND(ISNUMBER(M18),M18=INT(M18),M18>=0,M18<=99),M18,0))/100,0)*G18*gg_rate,6),0)/100,"") | AB18: =IF(C18="","",TRIM(IF(AND(E18="ΝΑΙ",ISNUMBER(L18)),IF(L18=0,"Συνοδός με 0 €; Τον πληρώνει ο ανάδοχος (§4.3.2.2). ",""),"")&IF(ISNUMBER(T18),IF(T18<0,"Ζημιά και με 0%. ",""),"")&IF(AND(N18="ΝΑΙ",NOT(ISNUMBER(O18))),"Λείπει η ημερομηνία απόφασης. ","")))
A19: 14 | P19: =AND(inputs_ok,C19<>"",OR(E19="ΝΑΙ",E19="ΟΧΙ"),ISNUMBER(F19),F19>0,ISNUMBER(G19),G19>0,ISNUMBER(H19),ISNUMBER(J19),ISNUMBER(K19),OR(E19="ΟΧΙ",ISNUMBER(L19))) | Q19: =IF(P19,G19/years*paid_share,"") | R19: =IF(P19,J19*(fuel_cons/100*fuel_price+wear)+IF(E19="ΝΑΙ",L19,0)+ins_year/Q19+K19*opp_rate+(2*bank_fee+bank_rate*Z19*gp_months/12)/(G19*paid_share),"") | S19: =IF(P19,ded_rate+gg_rate*bank_rate*gg_months/12/paid_share,"") | T19: =IF(P19,'Πλέγμα'!O6,"λείπουν στοιχεία") | U19: =IF(P19,T19*Q19,"") | V19: =IF(NOT(P19),"λείπουν στοιχεία",IF(T19<0,"καμία: ζημιά και με 0%",_xlfn.MAXIFS('Πλέγμα'!$A$6:$A$105,'Πλέγμα'!O$6:O$105,">=0"))) | W19: =IF(OR(NOT(P19),M19=""),"",IF(AND(ISNUMBER(M19),M19=INT(M19),M19>=0,M19<=99),INDEX('Πλέγμα'!O$6:O$105,M19+1),"ακέραια έκπτωση 0–99")) | X19: =IF(ISNUMBER(W19),W19*Q19,"") | Y19: =IF(NOT(P19),"",IF(ISNUMBER(W19),W19,T19)-J19*fuel_cons/100*fuel_price*fuel_scn) | Z19: =IF(ISNUMBER(H19),ROUNDUP(ROUND(ROUND(H19*100,0)*gp_rate,6),0)/100,"") | AA19: =IF(AND(ISNUMBER(F19),ISNUMBER(G19)),ROUNDUP(ROUND(ROUND(ROUND(F19*100,0)*(100-IF(AND(ISNUMBER(M19),M19=INT(M19),M19>=0,M19<=99),M19,0))/100,0)*G19*gg_rate,6),0)/100,"") | AB19: =IF(C19="","",TRIM(IF(AND(E19="ΝΑΙ",ISNUMBER(L19)),IF(L19=0,"Συνοδός με 0 €; Τον πληρώνει ο ανάδοχος (§4.3.2.2). ",""),"")&IF(ISNUMBER(T19),IF(T19<0,"Ζημιά και με 0%. ",""),"")&IF(AND(N19="ΝΑΙ",NOT(ISNUMBER(O19))),"Λείπει η ημερομηνία απόφασης. ","")))
A20: 15 | P20: =AND(inputs_ok,C20<>"",OR(E20="ΝΑΙ",E20="ΟΧΙ"),ISNUMBER(F20),F20>0,ISNUMBER(G20),G20>0,ISNUMBER(H20),ISNUMBER(J20),ISNUMBER(K20),OR(E20="ΟΧΙ",ISNUMBER(L20))) | Q20: =IF(P20,G20/years*paid_share,"") | R20: =IF(P20,J20*(fuel_cons/100*fuel_price+wear)+IF(E20="ΝΑΙ",L20,0)+ins_year/Q20+K20*opp_rate+(2*bank_fee+bank_rate*Z20*gp_months/12)/(G20*paid_share),"") | S20: =IF(P20,ded_rate+gg_rate*bank_rate*gg_months/12/paid_share,"") | T20: =IF(P20,'Πλέγμα'!P6,"λείπουν στοιχεία") | U20: =IF(P20,T20*Q20,"") | V20: =IF(NOT(P20),"λείπουν στοιχεία",IF(T20<0,"καμία: ζημιά και με 0%",_xlfn.MAXIFS('Πλέγμα'!$A$6:$A$105,'Πλέγμα'!P$6:P$105,">=0"))) | W20: =IF(OR(NOT(P20),M20=""),"",IF(AND(ISNUMBER(M20),M20=INT(M20),M20>=0,M20<=99),INDEX('Πλέγμα'!P$6:P$105,M20+1),"ακέραια έκπτωση 0–99")) | X20: =IF(ISNUMBER(W20),W20*Q20,"") | Y20: =IF(NOT(P20),"",IF(ISNUMBER(W20),W20,T20)-J20*fuel_cons/100*fuel_price*fuel_scn) | Z20: =IF(ISNUMBER(H20),ROUNDUP(ROUND(ROUND(H20*100,0)*gp_rate,6),0)/100,"") | AA20: =IF(AND(ISNUMBER(F20),ISNUMBER(G20)),ROUNDUP(ROUND(ROUND(ROUND(F20*100,0)*(100-IF(AND(ISNUMBER(M20),M20=INT(M20),M20>=0,M20<=99),M20,0))/100,0)*G20*gg_rate,6),0)/100,"") | AB20: =IF(C20="","",TRIM(IF(AND(E20="ΝΑΙ",ISNUMBER(L20)),IF(L20=0,"Συνοδός με 0 €; Τον πληρώνει ο ανάδοχος (§4.3.2.2). ",""),"")&IF(ISNUMBER(T20),IF(T20<0,"Ζημιά και με 0%. ",""),"")&IF(AND(N20="ΝΑΙ",NOT(ISNUMBER(O20))),"Λείπει η ημερομηνία απόφασης. ","")))

Sheet Πλέγμα
A1: Πλέγμα: καθαρό ανά ημέρα (€) για κάθε ακέραια έκπτωση
A2: Δεν αλλάζεις τίποτα εδώ. Κάθε στήλη είναι μία γραμμή του φύλλου Δρομολόγια, με την ίδια σειρά. Κόκκινο = ζημιά.
B4: =IF('Δρομολόγια'!C6="","",'Δρομολόγια'!C6) | C4: =IF('Δρομολόγια'!C7="","",'Δρομολόγια'!C7) | D4: =IF('Δρομολόγια'!C8="","",'Δρομολόγια'!C8) | E4: =IF('Δρομολόγια'!C9="","",'Δρομολόγια'!C9) | F4: =IF('Δρομολόγια'!C10="","",'Δρομολόγια'!C10) | G4: =IF('Δρομολόγια'!C11="","",'Δρομολόγια'!C11) | H4: =IF('Δρομολόγια'!C12="","",'Δρομολόγια'!C12) | I4: =IF('Δρομολόγια'!C13="","",'Δρομολόγια'!C13) | J4: =IF('Δρομολόγια'!C14="","",'Δρομολόγια'!C14) | K4: =IF('Δρομολόγια'!C15="","",'Δρομολόγια'!C15) | L4: =IF('Δρομολόγια'!C16="","",'Δρομολόγια'!C16) | M4: =IF('Δρομολόγια'!C17="","",'Δρομολόγια'!C17) | N4: =IF('Δρομολόγια'!C18="","",'Δρομολόγια'!C18) | O4: =IF('Δρομολόγια'!C19="","",'Δρομολόγια'!C19) | P4: =IF('Δρομολόγια'!C20="","",'Δρομολόγια'!C20)
A5: Έκπτωση % | B5: #1 | C5: #2 | D5: #3 | E5: #4 | F5: #5 | G5: #6 | H5: #7 | I5: #8 | J5: #9 | K5: #10 | L5: #11 | M5: #12 | N5: #13 | O5: #14 | P5: #15 | Q5: Ολογράφως (για το Υπόδειγμα)
A6: 0 | B6: =IF('Δρομολόγια'!$P$6,ROUND(ROUND('Δρομολόγια'!$F$6*100,0)*(100-$A6)/100,0)/100*(1-'Δρομολόγια'!$S$6)-'Δρομολόγια'!$R$6,"") | C6: =IF('Δρομολόγια'!$P$7,ROUND(ROUND('Δρομολόγια'!$F$7*100,0)*(100-$A6)/100,0)/100*(1-'Δρομολόγια'!$S$7)-'Δρομολόγια'!$R$7,"") | D6: =IF('Δρομολόγια'!$P$8,ROUND(ROUND('Δρομολόγια'!$F$8*100,0)*(100-$A6)/100,0)/100*(1-'Δρομολόγια'!$S$8)-'Δρομολόγια'!$R$8,"") | E6: =IF('Δρομολόγια'!$P$9,ROUND(ROUND('Δρομολόγια'!$F$9*100,0)*(100-$A6)/100,0)/100*(1-'Δρομολόγια'!$S$9)-'Δρομολόγια'!$R$9,"") | F6: =IF('Δρομολόγια'!$P$10,ROUND(ROUND('Δρομολόγια'!$F$10*100,0)*(100-$A6)/100,0)/100*(1-'Δρομολόγια'!$S$10)-'Δρομολόγια'!$R$10,"") | G6: =IF('Δρομολόγια'!$P$11,ROUND(ROUND('Δρομολόγια'!$F$11*100,0)*(100-$A6)/100,0)/100*(1-'Δρομολόγια'!$S$11)-'Δρομολόγια'!$R$11,"") | H6: =IF('Δρομολόγια'!$P$12,ROUND(ROUND('Δρομολόγια'!$F$12*100,0)*(100-$A6)/100,0)/100*(1-'Δρομολόγια'!$S$12)-'Δρομολόγια'!$R$12,"") | I6: =IF('Δρομολόγια'!$P$13,ROUND(ROUND('Δρομολόγια'!$F$13*100,0)*(100-$A6)/100,0)/100*(1-'Δρομολόγια'!$S$13)-'Δρομολόγια'!$R$13,"") | J6: =IF('Δρομολόγια'!$P$14,ROUND(ROUND('Δρομολόγια'!$F$14*100,0)*(100-$A6)/100,0)/100*(1-'Δρομολόγια'!$S$14)-'Δρομολόγια'!$R$14,"") | K6: =IF('Δρομολόγια'!$P$15,ROUND(ROUND('Δρομολόγια'!$F$15*100,0)*(100-$A6)/100,0)/100*(1-'Δρομολόγια'!$S$15)-'Δρομολόγια'!$R$15,"") | L6: =IF('Δρομολόγια'!$P$16,ROUND(ROUND('Δρομολόγια'!$F$16*100,0)*(100-$A6)/100,0)/100*(1-'Δρομολόγια'!$S$16)-'Δρομολόγια'!$R$16,"") | M6: =IF('Δρομολόγια'!$P$17,ROUND(ROUND('Δρομολόγια'!$F$17*100,0)*(100-$A6)/100,0)/100*(1-'Δρομολόγια'!$S$17)-'Δρομολόγια'!$R$17,"") | N6: =IF('Δρομολόγια'!$P$18,ROUND(ROUND('Δρομολόγια'!$F$18*100,0)*(100-$A6)/100,0)/100*(1-'Δρομολόγια'!$S$18)-'Δρομολόγια'!$R$18,"") | O6: =IF('Δρομολόγια'!$P$19,ROUND(ROUND('Δρομολόγια'!$F$19*100,0)*(100-$A6)/100,0)/100*(1-'Δρομολόγια'!$S$19)-'Δρομολόγια'!$R$19,"") | P6: =IF('Δρομολόγια'!$P$20,ROUND(ROUND('Δρομολόγια'!$F$20*100,0)*(100-$A6)/100,0)/100*(1-'Δρομολόγια'!$S$20)-'Δρομολόγια'!$R$20,"") | Q6: μηδέν
A7: 1 | B7: =IF('Δρομολόγια'!$P$6,ROUND(ROUND('Δρομολόγια'!$F$6*100,0)*(100-$A7)/100,0)/100*(1-'Δρομολόγια'!$S$6)-'Δρομολόγια'!$R$6,"") | C7: =IF('Δρομολόγια'!$P$7,ROUND(ROUND('Δρομολόγια'!$F$7*100,0)*(100-$A7)/100,0)/100*(1-'Δρομολόγια'!$S$7)-'Δρομολόγια'!$R$7,"") | D7: =IF('Δρομολόγια'!$P$8,ROUND(ROUND('Δρομολόγια'!$F$8*100,0)*(100-$A7)/100,0)/100*(1-'Δρομολόγια'!$S$8)-'Δρομολόγια'!$R$8,"") | E7: =IF('Δρομολόγια'!$P$9,ROUND(ROUND('Δρομολόγια'!$F$9*100,0)*(100-$A7)/100,0)/100*(1-'Δρομολόγια'!$S$9)-'Δρομολόγια'!$R$9,"") | F7: =IF('Δρομολόγια'!$P$10,ROUND(ROUND('Δρομολόγια'!$F$10*100,0)*(100-$A7)/100,0)/100*(1-'Δρομολόγια'!$S$10)-'Δρομολόγια'!$R$10,"") | G7: =IF('Δρομολόγια'!$P$11,ROUND(ROUND('Δρομολόγια'!$F$11*100,0)*(100-$A7)/100,0)/100*(1-'Δρομολόγια'!$S$11)-'Δρομολόγια'!$R$11,"") | H7: =IF('Δρομολόγια'!$P$12,ROUND(ROUND('Δρομολόγια'!$F$12*100,0)*(100-$A7)/100,0)/100*(1-'Δρομολόγια'!$S$12)-'Δρομολόγια'!$R$12,"") | I7: =IF('Δρομολόγια'!$P$13,ROUND(ROUND('Δρομολόγια'!$F$13*100,0)*(100-$A7)/100,0)/100*(1-'Δρομολόγια'!$S$13)-'Δρομολόγια'!$R$13,"") | J7: =IF('Δρομολόγια'!$P$14,ROUND(ROUND('Δρομολόγια'!$F$14*100,0)*(100-$A7)/100,0)/100*(1-'Δρομολόγια'!$S$14)-'Δρομολόγια'!$R$14,"") | K7: =IF('Δρομολόγια'!$P$15,ROUND(ROUND('Δρομολόγια'!$F$15*100,0)*(100-$A7)/100,0)/100*(1-'Δρομολόγια'!$S$15)-'Δρομολόγια'!$R$15,"") | L7: =IF('Δρομολόγια'!$P$16,ROUND(ROUND('Δρομολόγια'!$F$16*100,0)*(100-$A7)/100,0)/100*(1-'Δρομολόγια'!$S$16)-'Δρομολόγια'!$R$16,"") | M7: =IF('Δρομολόγια'!$P$17,ROUND(ROUND('Δρομολόγια'!$F$17*100,0)*(100-$A7)/100,0)/100*(1-'Δρομολόγια'!$S$17)-'Δρομολόγια'!$R$17,"") | N7: =IF('Δρομολόγια'!$P$18,ROUND(ROUND('Δρομολόγια'!$F$18*100,0)*(100-$A7)/100,0)/100*(1-'Δρομολόγια'!$S$18)-'Δρομολόγια'!$R$18,"") | O7: =IF('Δρομολόγια'!$P$19,ROUND(ROUND('Δρομολόγια'!$F$19*100,0)*(100-$A7)/100,0)/100*(1-'Δρομολόγια'!$S$19)-'Δρομολόγια'!$R$19,"") | P7: =IF('Δρομολόγια'!$P$20,ROUND(ROUND('Δρομολόγια'!$F$20*100,0)*(100-$A7)/100,0)/100*(1-'Δρομολόγια'!$S$20)-'Δρομολόγια'!$R$20,"") | Q7: ένα
A8: 2 | B8: =IF('Δρομολόγια'!$P$6,ROUND(ROUND('Δρομολόγια'!$F$6*100,0)*(100-$A8)/100,0)/100*(1-'Δρομολόγια'!$S$6)-'Δρομολόγια'!$R$6,"") | C8: =IF('Δρομολόγια'!$P$7,ROUND(ROUND('Δρομολόγια'!$F$7*100,0)*(100-$A8)/100,0)/100*(1-'Δρομολόγια'!$S$7)-'Δρομολόγια'!$R$7,"") | D8: =IF('Δρομολόγια'!$P$8,ROUND(ROUND('Δρομολόγια'!$F$8*100,0)*(100-$A8)/100,0)/100*(1-'Δρομολόγια'!$S$8)-'Δρομολόγια'!$R$8,"") | E8: =IF('Δρομολόγια'!$P$9,ROUND(ROUND('Δρομολόγια'!$F$9*100,0)*(100-$A8)/100,0)/100*(1-'Δρομολόγια'!$S$9)-'Δρομολόγια'!$R$9,"") | F8: =IF('Δρομολόγια'!$P$10,ROUND(ROUND('Δρομολόγια'!$F$10*100,0)*(100-$A8)/100,0)/100*(1-'Δρομολόγια'!$S$10)-'Δρομολόγια'!$R$10,"") | G8: =IF('Δρομολόγια'!$P$11,ROUND(ROUND('Δρομολόγια'!$F$11*100,0)*(100-$A8)/100,0)/100*(1-'Δρομολόγια'!$S$11)-'Δρομολόγια'!$R$11,"") | H8: =IF('Δρομολόγια'!$P$12,ROUND(ROUND('Δρομολόγια'!$F$12*100,0)*(100-$A8)/100,0)/100*(1-'Δρομολόγια'!$S$12)-'Δρομολόγια'!$R$12,"") | I8: =IF('Δρομολόγια'!$P$13,ROUND(ROUND('Δρομολόγια'!$F$13*100,0)*(100-$A8)/100,0)/100*(1-'Δρομολόγια'!$S$13)-'Δρομολόγια'!$R$13,"") | J8: =IF('Δρομολόγια'!$P$14,ROUND(ROUND('Δρομολόγια'!$F$14*100,0)*(100-$A8)/100,0)/100*(1-'Δρομολόγια'!$S$14)-'Δρομολόγια'!$R$14,"") | K8: =IF('Δρομολόγια'!$P$15,ROUND(ROUND('Δρομολόγια'!$F$15*100,0)*(100-$A8)/100,0)/100*(1-'Δρομολόγια'!$S$15)-'Δρομολόγια'!$R$15,"") | L8: =IF('Δρομολόγια'!$P$16,ROUND(ROUND('Δρομολόγια'!$F$16*100,0)*(100-$A8)/100,0)/100*(1-'Δρομολόγια'!$S$16)-'Δρομολόγια'!$R$16,"") | M8: =IF('Δρομολόγια'!$P$17,ROUND(ROUND('Δρομολόγια'!$F$17*100,0)*(100-$A8)/100,0)/100*(1-'Δρομολόγια'!$S$17)-'Δρομολόγια'!$R$17,"") | N8: =IF('Δρομολόγια'!$P$18,ROUND(ROUND('Δρομολόγια'!$F$18*100,0)*(100-$A8)/100,0)/100*(1-'Δρομολόγια'!$S$18)-'Δρομολόγια'!$R$18,"") | O8: =IF('Δρομολόγια'!$P$19,ROUND(ROUND('Δρομολόγια'!$F$19*100,0)*(100-$A8)/100,0)/100*(1-'Δρομολόγια'!$S$19)-'Δρομολόγια'!$R$19,"") | P8: =IF('Δρομολόγια'!$P$20,ROUND(ROUND('Δρομολόγια'!$F$20*100,0)*(100-$A8)/100,0)/100*(1-'Δρομολόγια'!$S$20)-'Δρομολόγια'!$R$20,"") | Q8: δύο
A9: 3 | B9: =IF('Δρομολόγια'!$P$6,ROUND(ROUND('Δρομολόγια'!$F$6*100,0)*(100-$A9)/100,0)/100*(1-'Δρομολόγια'!$S$6)-'Δρομολόγια'!$R$6,"") | C9: =IF('Δρομολόγια'!$P$7,ROUND(ROUND('Δρομολόγια'!$F$7*100,0)*(100-$A9)/100,0)/100*(1-'Δρομολόγια'!$S$7)-'Δρομολόγια'!$R$7,"") | D9: =IF('Δρομολόγια'!$P$8,ROUND(ROUND('Δρομολόγια'!$F$8*100,0)*(100-$A9)/100,0)/100*(1-'Δρομολόγια'!$S$8)-'Δρομολόγια'!$R$8,"") | E9: =IF('Δρομολόγια'!$P$9,ROUND(ROUND('Δρομολόγια'!$F$9*100,0)*(100-$A9)/100,0)/100*(1-'Δρομολόγια'!$S$9)-'Δρομολόγια'!$R$9,"") | F9: =IF('Δρομολόγια'!$P$10,ROUND(ROUND('Δρομολόγια'!$F$10*100,0)*(100-$A9)/100,0)/100*(1-'Δρομολόγια'!$S$10)-'Δρομολόγια'!$R$10,"") | G9: =IF('Δρομολόγια'!$P$11,ROUND(ROUND('Δρομολόγια'!$F$11*100,0)*(100-$A9)/100,0)/100*(1-'Δρομολόγια'!$S$11)-'Δρομολόγια'!$R$11,"") | H9: =IF('Δρομολόγια'!$P$12,ROUND(ROUND('Δρομολόγια'!$F$12*100,0)*(100-$A9)/100,0)/100*(1-'Δρομολόγια'!$S$12)-'Δρομολόγια'!$R$12,"") | I9: =IF('Δρομολόγια'!$P$13,ROUND(ROUND('Δρομολόγια'!$F$13*100,0)*(100-$A9)/100,0)/100*(1-'Δρομολόγια'!$S$13)-'Δρομολόγια'!$R$13,"") | J9: =IF('Δρομολόγια'!$P$14,ROUND(ROUND('Δρομολόγια'!$F$14*100,0)*(100-$A9)/100,0)/100*(1-'Δρομολόγια'!$S$14)-'Δρομολόγια'!$R$14,"") | K9: =IF('Δρομολόγια'!$P$15,ROUND(ROUND('Δρομολόγια'!$F$15*100,0)*(100-$A9)/100,0)/100*(1-'Δρομολόγια'!$S$15)-'Δρομολόγια'!$R$15,"") | L9: =IF('Δρομολόγια'!$P$16,ROUND(ROUND('Δρομολόγια'!$F$16*100,0)*(100-$A9)/100,0)/100*(1-'Δρομολόγια'!$S$16)-'Δρομολόγια'!$R$16,"") | M9: =IF('Δρομολόγια'!$P$17,ROUND(ROUND('Δρομολόγια'!$F$17*100,0)*(100-$A9)/100,0)/100*(1-'Δρομολόγια'!$S$17)-'Δρομολόγια'!$R$17,"") | N9: =IF('Δρομολόγια'!$P$18,ROUND(ROUND('Δρομολόγια'!$F$18*100,0)*(100-$A9)/100,0)/100*(1-'Δρομολόγια'!$S$18)-'Δρομολόγια'!$R$18,"") | O9: =IF('Δρομολόγια'!$P$19,ROUND(ROUND('Δρομολόγια'!$F$19*100,0)*(100-$A9)/100,0)/100*(1-'Δρομολόγια'!$S$19)-'Δρομολόγια'!$R$19,"") | P9: =IF('Δρομολόγια'!$P$20,ROUND(ROUND('Δρομολόγια'!$F$20*100,0)*(100-$A9)/100,0)/100*(1-'Δρομολόγια'!$S$20)-'Δρομολόγια'!$R$20,"") | Q9: τρία
A10: 4 | B10: =IF('Δρομολόγια'!$P$6,ROUND(ROUND('Δρομολόγια'!$F$6*100,0)*(100-$A10)/100,0)/100*(1-'Δρομολόγια'!$S$6)-'Δρομολόγια'!$R$6,"") | C10: =IF('Δρομολόγια'!$P$7,ROUND(ROUND('Δρομολόγια'!$F$7*100,0)*(100-$A10)/100,0)/100*(1-'Δρομολόγια'!$S$7)-'Δρομολόγια'!$R$7,"") | D10: =IF('Δρομολόγια'!$P$8,ROUND(ROUND('Δρομολόγια'!$F$8*100,0)*(100-$A10)/100,0)/100*(1-'Δρομολόγια'!$S$8)-'Δρομολόγια'!$R$8,"") | E10: =IF('Δρομολόγια'!$P$9,ROUND(ROUND('Δρομολόγια'!$F$9*100,0)*(100-$A10)/100,0)/100*(1-'Δρομολόγια'!$S$9)-'Δρομολόγια'!$R$9,"") | F10: =IF('Δρομολόγια'!$P$10,ROUND(ROUND('Δρομολόγια'!$F$10*100,0)*(100-$A10)/100,0)/100*(1-'Δρομολόγια'!$S$10)-'Δρομολόγια'!$R$10,"") | G10: =IF('Δρομολόγια'!$P$11,ROUND(ROUND('Δρομολόγια'!$F$11*100,0)*(100-$A10)/100,0)/100*(1-'Δρομολόγια'!$S$11)-'Δρομολόγια'!$R$11,"") | H10: =IF('Δρομολόγια'!$P$12,ROUND(ROUND('Δρομολόγια'!$F$12*100,0)*(100-$A10)/100,0)/100*(1-'Δρομολόγια'!$S$12)-'Δρομολόγια'!$R$12,"") | I10: =IF('Δρομολόγια'!$P$13,ROUND(ROUND('Δρομολόγια'!$F$13*100,0)*(100-$A10)/100,0)/100*(1-'Δρομολόγια'!$S$13)-'Δρομολόγια'!$R$13,"") | J10: =IF('Δρομολόγια'!$P$14,ROUND(ROUND('Δρομολόγια'!$F$14*100,0)*(100-$A10)/100,0)/100*(1-'Δρομολόγια'!$S$14)-'Δρομολόγια'!$R$14,"") | K10: =IF('Δρομολόγια'!$P$15,ROUND(ROUND('Δρομολόγια'!$F$15*100,0)*(100-$A10)/100,0)/100*(1-'Δρομολόγια'!$S$15)-'Δρομολόγια'!$R$15,"") | L10: =IF('Δρομολόγια'!$P$16,ROUND(ROUND('Δρομολόγια'!$F$16*100,0)*(100-$A10)/100,0)/100*(1-'Δρομολόγια'!$S$16)-'Δρομολόγια'!$R$16,"") | M10: =IF('Δρομολόγια'!$P$17,ROUND(ROUND('Δρομολόγια'!$F$17*100,0)*(100-$A10)/100,0)/100*(1-'Δρομολόγια'!$S$17)-'Δρομολόγια'!$R$17,"") | N10: =IF('Δρομολόγια'!$P$18,ROUND(ROUND('Δρομολόγια'!$F$18*100,0)*(100-$A10)/100,0)/100*(1-'Δρομολόγια'!$S$18)-'Δρομολόγια'!$R$18,"") | O10: =IF('Δρομολόγια'!$P$19,ROUND(ROUND('Δρομολόγια'!$F$19*100,0)*(100-$A10)/100,0)/100*(1-'Δρομολόγια'!$S$19)-'Δρομολόγια'!$R$19,"") | P10: =IF('Δρομολόγια'!$P$20,ROUND(ROUND('Δρομολόγια'!$F$20*100,0)*(100-$A10)/100,0)/100*(1-'Δρομολόγια'!$S$20)-'Δρομολόγια'!$R$20,"") | Q10: τέσσερα
A11: 5 | B11: =IF('Δρομολόγια'!$P$6,ROUND(ROUND('Δρομολόγια'!$F$6*100,0)*(100-$A11)/100,0)/100*(1-'Δρομολόγια'!$S$6)-'Δρομολόγια'!$R$6,"") | C11: =IF('Δρομολόγια'!$P$7,ROUND(ROUND('Δρομολόγια'!$F$7*100,0)*(100-$A11)/100,0)/100*(1-'Δρομολόγια'!$S$7)-'Δρομολόγια'!$R$7,"") | D11: =IF('Δρομολόγια'!$P$8,ROUND(ROUND('Δρομολόγια'!$F$8*100,0)*(100-$A11)/100,0)/100*(1-'Δρομολόγια'!$S$8)-'Δρομολόγια'!$R$8,"") | E11: =IF('Δρομολόγια'!$P$9,ROUND(ROUND('Δρομολόγια'!$F$9*100,0)*(100-$A11)/100,0)/100*(1-'Δρομολόγια'!$S$9)-'Δρομολόγια'!$R$9,"") | F11: =IF('Δρομολόγια'!$P$10,ROUND(ROUND('Δρομολόγια'!$F$10*100,0)*(100-$A11)/100,0)/100*(1-'Δρομολόγια'!$S$10)-'Δρομολόγια'!$R$10,"") | G11: =IF('Δρομολόγια'!$P$11,ROUND(ROUND('Δρομολόγια'!$F$11*100,0)*(100-$A11)/100,0)/100*(1-'Δρομολόγια'!$S$11)-'Δρομολόγια'!$R$11,"") | H11: =IF('Δρομολόγια'!$P$12,ROUND(ROUND('Δρομολόγια'!$F$12*100,0)*(100-$A11)/100,0)/100*(1-'Δρομολόγια'!$S$12)-'Δρομολόγια'!$R$12,"") | I11: =IF('Δρομολόγια'!$P$13,ROUND(ROUND('Δρομολόγια'!$F$13*100,0)*(100-$A11)/100,0)/100*(1-'Δρομολόγια'!$S$13)-'Δρομολόγια'!$R$13,"") | J11: =IF('Δρομολόγια'!$P$14,ROUND(ROUND('Δρομολόγια'!$F$14*100,0)*(100-$A11)/100,0)/100*(1-'Δρομολόγια'!$S$14)-'Δρομολόγια'!$R$14,"") | K11: =IF('Δρομολόγια'!$P$15,ROUND(ROUND('Δρομολόγια'!$F$15*100,0)*(100-$A11)/100,0)/100*(1-'Δρομολόγια'!$S$15)-'Δρομολόγια'!$R$15,"") | L11: =IF('Δρομολόγια'!$P$16,ROUND(ROUND('Δρομολόγια'!$F$16*100,0)*(100-$A11)/100,0)/100*(1-'Δρομολόγια'!$S$16)-'Δρομολόγια'!$R$16,"") | M11: =IF('Δρομολόγια'!$P$17,ROUND(ROUND('Δρομολόγια'!$F$17*100,0)*(100-$A11)/100,0)/100*(1-'Δρομολόγια'!$S$17)-'Δρομολόγια'!$R$17,"") | N11: =IF('Δρομολόγια'!$P$18,ROUND(ROUND('Δρομολόγια'!$F$18*100,0)*(100-$A11)/100,0)/100*(1-'Δρομολόγια'!$S$18)-'Δρομολόγια'!$R$18,"") | O11: =IF('Δρομολόγια'!$P$19,ROUND(ROUND('Δρομολόγια'!$F$19*100,0)*(100-$A11)/100,0)/100*(1-'Δρομολόγια'!$S$19)-'Δρομολόγια'!$R$19,"") | P11: =IF('Δρομολόγια'!$P$20,ROUND(ROUND('Δρομολόγια'!$F$20*100,0)*(100-$A11)/100,0)/100*(1-'Δρομολόγια'!$S$20)-'Δρομολόγια'!$R$20,"") | Q11: πέντε
A12: 6 | B12: =IF('Δρομολόγια'!$P$6,ROUND(ROUND('Δρομολόγια'!$F$6*100,0)*(100-$A12)/100,0)/100*(1-'Δρομολόγια'!$S$6)-'Δρομολόγια'!$R$6,"") | C12: =IF('Δρομολόγια'!$P$7,ROUND(ROUND('Δρομολόγια'!$F$7*100,0)*(100-$A12)/100,0)/100*(1-'Δρομολόγια'!$S$7)-'Δρομολόγια'!$R$7,"") | D12: =IF('Δρομολόγια'!$P$8,ROUND(ROUND('Δρομολόγια'!$F$8*100,0)*(100-$A12)/100,0)/100*(1-'Δρομολόγια'!$S$8)-'Δρομολόγια'!$R$8,"") | E12: =IF('Δρομολόγια'!$P$9,ROUND(ROUND('Δρομολόγια'!$F$9*100,0)*(100-$A12)/100,0)/100*(1-'Δρομολόγια'!$S$9)-'Δρομολόγια'!$R$9,"") | F12: =IF('Δρομολόγια'!$P$10,ROUND(ROUND('Δρομολόγια'!$F$10*100,0)*(100-$A12)/100,0)/100*(1-'Δρομολόγια'!$S$10)-'Δρομολόγια'!$R$10,"") | G12: =IF('Δρομολόγια'!$P$11,ROUND(ROUND('Δρομολόγια'!$F$11*100,0)*(100-$A12)/100,0)/100*(1-'Δρομολόγια'!$S$11)-'Δρομολόγια'!$R$11,"") | H12: =IF('Δρομολόγια'!$P$12,ROUND(ROUND('Δρομολόγια'!$F$12*100,0)*(100-$A12)/100,0)/100*(1-'Δρομολόγια'!$S$12)-'Δρομολόγια'!$R$12,"") | I12: =IF('Δρομολόγια'!$P$13,ROUND(ROUND('Δρομολόγια'!$F$13*100,0)*(100-$A12)/100,0)/100*(1-'Δρομολόγια'!$S$13)-'Δρομολόγια'!$R$13,"") | J12: =IF('Δρομολόγια'!$P$14,ROUND(ROUND('Δρομολόγια'!$F$14*100,0)*(100-$A12)/100,0)/100*(1-'Δρομολόγια'!$S$14)-'Δρομολόγια'!$R$14,"") | K12: =IF('Δρομολόγια'!$P$15,ROUND(ROUND('Δρομολόγια'!$F$15*100,0)*(100-$A12)/100,0)/100*(1-'Δρομολόγια'!$S$15)-'Δρομολόγια'!$R$15,"") | L12: =IF('Δρομολόγια'!$P$16,ROUND(ROUND('Δρομολόγια'!$F$16*100,0)*(100-$A12)/100,0)/100*(1-'Δρομολόγια'!$S$16)-'Δρομολόγια'!$R$16,"") | M12: =IF('Δρομολόγια'!$P$17,ROUND(ROUND('Δρομολόγια'!$F$17*100,0)*(100-$A12)/100,0)/100*(1-'Δρομολόγια'!$S$17)-'Δρομολόγια'!$R$17,"") | N12: =IF('Δρομολόγια'!$P$18,ROUND(ROUND('Δρομολόγια'!$F$18*100,0)*(100-$A12)/100,0)/100*(1-'Δρομολόγια'!$S$18)-'Δρομολόγια'!$R$18,"") | O12: =IF('Δρομολόγια'!$P$19,ROUND(ROUND('Δρομολόγια'!$F$19*100,0)*(100-$A12)/100,0)/100*(1-'Δρομολόγια'!$S$19)-'Δρομολόγια'!$R$19,"") | P12: =IF('Δρομολόγια'!$P$20,ROUND(ROUND('Δρομολόγια'!$F$20*100,0)*(100-$A12)/100,0)/100*(1-'Δρομολόγια'!$S$20)-'Δρομολόγια'!$R$20,"") | Q12: έξι
A13: 7 | B13: =IF('Δρομολόγια'!$P$6,ROUND(ROUND('Δρομολόγια'!$F$6*100,0)*(100-$A13)/100,0)/100*(1-'Δρομολόγια'!$S$6)-'Δρομολόγια'!$R$6,"") | C13: =IF('Δρομολόγια'!$P$7,ROUND(ROUND('Δρομολόγια'!$F$7*100,0)*(100-$A13)/100,0)/100*(1-'Δρομολόγια'!$S$7)-'Δρομολόγια'!$R$7,"") | D13: =IF('Δρομολόγια'!$P$8,ROUND(ROUND('Δρομολόγια'!$F$8*100,0)*(100-$A13)/100,0)/100*(1-'Δρομολόγια'!$S$8)-'Δρομολόγια'!$R$8,"") | E13: =IF('Δρομολόγια'!$P$9,ROUND(ROUND('Δρομολόγια'!$F$9*100,0)*(100-$A13)/100,0)/100*(1-'Δρομολόγια'!$S$9)-'Δρομολόγια'!$R$9,"") | F13: =IF('Δρομολόγια'!$P$10,ROUND(ROUND('Δρομολόγια'!$F$10*100,0)*(100-$A13)/100,0)/100*(1-'Δρομολόγια'!$S$10)-'Δρομολόγια'!$R$10,"") | G13: =IF('Δρομολόγια'!$P$11,ROUND(ROUND('Δρομολόγια'!$F$11*100,0)*(100-$A13)/100,0)/100*(1-'Δρομολόγια'!$S$11)-'Δρομολόγια'!$R$11,"") | H13: =IF('Δρομολόγια'!$P$12,ROUND(ROUND('Δρομολόγια'!$F$12*100,0)*(100-$A13)/100,0)/100*(1-'Δρομολόγια'!$S$12)-'Δρομολόγια'!$R$12,"") | I13: =IF('Δρομολόγια'!$P$13,ROUND(ROUND('Δρομολόγια'!$F$13*100,0)*(100-$A13)/100,0)/100*(1-'Δρομολόγια'!$S$13)-'Δρομολόγια'!$R$13,"") | J13: =IF('Δρομολόγια'!$P$14,ROUND(ROUND('Δρομολόγια'!$F$14*100,0)*(100-$A13)/100,0)/100*(1-'Δρομολόγια'!$S$14)-'Δρομολόγια'!$R$14,"") | K13: =IF('Δρομολόγια'!$P$15,ROUND(ROUND('Δρομολόγια'!$F$15*100,0)*(100-$A13)/100,0)/100*(1-'Δρομολόγια'!$S$15)-'Δρομολόγια'!$R$15,"") | L13: =IF('Δρομολόγια'!$P$16,ROUND(ROUND('Δρομολόγια'!$F$16*100,0)*(100-$A13)/100,0)/100*(1-'Δρομολόγια'!$S$16)-'Δρομολόγια'!$R$16,"") | M13: =IF('Δρομολόγια'!$P$17,ROUND(ROUND('Δρομολόγια'!$F$17*100,0)*(100-$A13)/100,0)/100*(1-'Δρομολόγια'!$S$17)-'Δρομολόγια'!$R$17,"") | N13: =IF('Δρομολόγια'!$P$18,ROUND(ROUND('Δρομολόγια'!$F$18*100,0)*(100-$A13)/100,0)/100*(1-'Δρομολόγια'!$S$18)-'Δρομολόγια'!$R$18,"") | O13: =IF('Δρομολόγια'!$P$19,ROUND(ROUND('Δρομολόγια'!$F$19*100,0)*(100-$A13)/100,0)/100*(1-'Δρομολόγια'!$S$19)-'Δρομολόγια'!$R$19,"") | P13: =IF('Δρομολόγια'!$P$20,ROUND(ROUND('Δρομολόγια'!$F$20*100,0)*(100-$A13)/100,0)/100*(1-'Δρομολόγια'!$S$20)-'Δρομολόγια'!$R$20,"") | Q13: επτά
A14: 8 | B14: =IF('Δρομολόγια'!$P$6,ROUND(ROUND('Δρομολόγια'!$F$6*100,0)*(100-$A14)/100,0)/100*(1-'Δρομολόγια'!$S$6)-'Δρομολόγια'!$R$6,"") | C14: =IF('Δρομολόγια'!$P$7,ROUND(ROUND('Δρομολόγια'!$F$7*100,0)*(100-$A14)/100,0)/100*(1-'Δρομολόγια'!$S$7)-'Δρομολόγια'!$R$7,"") | D14: =IF('Δρομολόγια'!$P$8,ROUND(ROUND('Δρομολόγια'!$F$8*100,0)*(100-$A14)/100,0)/100*(1-'Δρομολόγια'!$S$8)-'Δρομολόγια'!$R$8,"") | E14: =IF('Δρομολόγια'!$P$9,ROUND(ROUND('Δρομολόγια'!$F$9*100,0)*(100-$A14)/100,0)/100*(1-'Δρομολόγια'!$S$9)-'Δρομολόγια'!$R$9,"") | F14: =IF('Δρομολόγια'!$P$10,ROUND(ROUND('Δρομολόγια'!$F$10*100,0)*(100-$A14)/100,0)/100*(1-'Δρομολόγια'!$S$10)-'Δρομολόγια'!$R$10,"") | G14: =IF('Δρομολόγια'!$P$11,ROUND(ROUND('Δρομολόγια'!$F$11*100,0)*(100-$A14)/100,0)/100*(1-'Δρομολόγια'!$S$11)-'Δρομολόγια'!$R$11,"") | H14: =IF('Δρομολόγια'!$P$12,ROUND(ROUND('Δρομολόγια'!$F$12*100,0)*(100-$A14)/100,0)/100*(1-'Δρομολόγια'!$S$12)-'Δρομολόγια'!$R$12,"") | I14: =IF('Δρομολόγια'!$P$13,ROUND(ROUND('Δρομολόγια'!$F$13*100,0)*(100-$A14)/100,0)/100*(1-'Δρομολόγια'!$S$13)-'Δρομολόγια'!$R$13,"") | J14: =IF('Δρομολόγια'!$P$14,ROUND(ROUND('Δρομολόγια'!$F$14*100,0)*(100-$A14)/100,0)/100*(1-'Δρομολόγια'!$S$14)-'Δρομολόγια'!$R$14,"") | K14: =IF('Δρομολόγια'!$P$15,ROUND(ROUND('Δρομολόγια'!$F$15*100,0)*(100-$A14)/100,0)/100*(1-'Δρομολόγια'!$S$15)-'Δρομολόγια'!$R$15,"") | L14: =IF('Δρομολόγια'!$P$16,ROUND(ROUND('Δρομολόγια'!$F$16*100,0)*(100-$A14)/100,0)/100*(1-'Δρομολόγια'!$S$16)-'Δρομολόγια'!$R$16,"") | M14: =IF('Δρομολόγια'!$P$17,ROUND(ROUND('Δρομολόγια'!$F$17*100,0)*(100-$A14)/100,0)/100*(1-'Δρομολόγια'!$S$17)-'Δρομολόγια'!$R$17,"") | N14: =IF('Δρομολόγια'!$P$18,ROUND(ROUND('Δρομολόγια'!$F$18*100,0)*(100-$A14)/100,0)/100*(1-'Δρομολόγια'!$S$18)-'Δρομολόγια'!$R$18,"") | O14: =IF('Δρομολόγια'!$P$19,ROUND(ROUND('Δρομολόγια'!$F$19*100,0)*(100-$A14)/100,0)/100*(1-'Δρομολόγια'!$S$19)-'Δρομολόγια'!$R$19,"") | P14: =IF('Δρομολόγια'!$P$20,ROUND(ROUND('Δρομολόγια'!$F$20*100,0)*(100-$A14)/100,0)/100*(1-'Δρομολόγια'!$S$20)-'Δρομολόγια'!$R$20,"") | Q14: οκτώ
A15: 9 | B15: =IF('Δρομολόγια'!$P$6,ROUND(ROUND('Δρομολόγια'!$F$6*100,0)*(100-$A15)/100,0)/100*(1-'Δρομολόγια'!$S$6)-'Δρομολόγια'!$R$6,"") | C15: =IF('Δρομολόγια'!$P$7,ROUND(ROUND('Δρομολόγια'!$F$7*100,0)*(100-$A15)/100,0)/100*(1-'Δρομολόγια'!$S$7)-'Δρομολόγια'!$R$7,"") | D15: =IF('Δρομολόγια'!$P$8,ROUND(ROUND('Δρομολόγια'!$F$8*100,0)*(100-$A15)/100,0)/100*(1-'Δρομολόγια'!$S$8)-'Δρομολόγια'!$R$8,"") | E15: =IF('Δρομολόγια'!$P$9,ROUND(ROUND('Δρομολόγια'!$F$9*100,0)*(100-$A15)/100,0)/100*(1-'Δρομολόγια'!$S$9)-'Δρομολόγια'!$R$9,"") | F15: =IF('Δρομολόγια'!$P$10,ROUND(ROUND('Δρομολόγια'!$F$10*100,0)*(100-$A15)/100,0)/100*(1-'Δρομολόγια'!$S$10)-'Δρομολόγια'!$R$10,"") | G15: =IF('Δρομολόγια'!$P$11,ROUND(ROUND('Δρομολόγια'!$F$11*100,0)*(100-$A15)/100,0)/100*(1-'Δρομολόγια'!$S$11)-'Δρομολόγια'!$R$11,"") | H15: =IF('Δρομολόγια'!$P$12,ROUND(ROUND('Δρομολόγια'!$F$12*100,0)*(100-$A15)/100,0)/100*(1-'Δρομολόγια'!$S$12)-'Δρομολόγια'!$R$12,"") | I15: =IF('Δρομολόγια'!$P$13,ROUND(ROUND('Δρομολόγια'!$F$13*100,0)*(100-$A15)/100,0)/100*(1-'Δρομολόγια'!$S$13)-'Δρομολόγια'!$R$13,"") | J15: =IF('Δρομολόγια'!$P$14,ROUND(ROUND('Δρομολόγια'!$F$14*100,0)*(100-$A15)/100,0)/100*(1-'Δρομολόγια'!$S$14)-'Δρομολόγια'!$R$14,"") | K15: =IF('Δρομολόγια'!$P$15,ROUND(ROUND('Δρομολόγια'!$F$15*100,0)*(100-$A15)/100,0)/100*(1-'Δρομολόγια'!$S$15)-'Δρομολόγια'!$R$15,"") | L15: =IF('Δρομολόγια'!$P$16,ROUND(ROUND('Δρομολόγια'!$F$16*100,0)*(100-$A15)/100,0)/100*(1-'Δρομολόγια'!$S$16)-'Δρομολόγια'!$R$16,"") | M15: =IF('Δρομολόγια'!$P$17,ROUND(ROUND('Δρομολόγια'!$F$17*100,0)*(100-$A15)/100,0)/100*(1-'Δρομολόγια'!$S$17)-'Δρομολόγια'!$R$17,"") | N15: =IF('Δρομολόγια'!$P$18,ROUND(ROUND('Δρομολόγια'!$F$18*100,0)*(100-$A15)/100,0)/100*(1-'Δρομολόγια'!$S$18)-'Δρομολόγια'!$R$18,"") | O15: =IF('Δρομολόγια'!$P$19,ROUND(ROUND('Δρομολόγια'!$F$19*100,0)*(100-$A15)/100,0)/100*(1-'Δρομολόγια'!$S$19)-'Δρομολόγια'!$R$19,"") | P15: =IF('Δρομολόγια'!$P$20,ROUND(ROUND('Δρομολόγια'!$F$20*100,0)*(100-$A15)/100,0)/100*(1-'Δρομολόγια'!$S$20)-'Δρομολόγια'!$R$20,"") | Q15: εννέα
A16: 10 | B16: =IF('Δρομολόγια'!$P$6,ROUND(ROUND('Δρομολόγια'!$F$6*100,0)*(100-$A16)/100,0)/100*(1-'Δρομολόγια'!$S$6)-'Δρομολόγια'!$R$6,"") | C16: =IF('Δρομολόγια'!$P$7,ROUND(ROUND('Δρομολόγια'!$F$7*100,0)*(100-$A16)/100,0)/100*(1-'Δρομολόγια'!$S$7)-'Δρομολόγια'!$R$7,"") | D16: =IF('Δρομολόγια'!$P$8,ROUND(ROUND('Δρομολόγια'!$F$8*100,0)*(100-$A16)/100,0)/100*(1-'Δρομολόγια'!$S$8)-'Δρομολόγια'!$R$8,"") | E16: =IF('Δρομολόγια'!$P$9,ROUND(ROUND('Δρομολόγια'!$F$9*100,0)*(100-$A16)/100,0)/100*(1-'Δρομολόγια'!$S$9)-'Δρομολόγια'!$R$9,"") | F16: =IF('Δρομολόγια'!$P$10,ROUND(ROUND('Δρομολόγια'!$F$10*100,0)*(100-$A16)/100,0)/100*(1-'Δρομολόγια'!$S$10)-'Δρομολόγια'!$R$10,"") | G16: =IF('Δρομολόγια'!$P$11,ROUND(ROUND('Δρομολόγια'!$F$11*100,0)*(100-$A16)/100,0)/100*(1-'Δρομολόγια'!$S$11)-'Δρομολόγια'!$R$11,"") | H16: =IF('Δρομολόγια'!$P$12,ROUND(ROUND('Δρομολόγια'!$F$12*100,0)*(100-$A16)/100,0)/100*(1-'Δρομολόγια'!$S$12)-'Δρομολόγια'!$R$12,"") | I16: =IF('Δρομολόγια'!$P$13,ROUND(ROUND('Δρομολόγια'!$F$13*100,0)*(100-$A16)/100,0)/100*(1-'Δρομολόγια'!$S$13)-'Δρομολόγια'!$R$13,"") | J16: =IF('Δρομολόγια'!$P$14,ROUND(ROUND('Δρομολόγια'!$F$14*100,0)*(100-$A16)/100,0)/100*(1-'Δρομολόγια'!$S$14)-'Δρομολόγια'!$R$14,"") | K16: =IF('Δρομολόγια'!$P$15,ROUND(ROUND('Δρομολόγια'!$F$15*100,0)*(100-$A16)/100,0)/100*(1-'Δρομολόγια'!$S$15)-'Δρομολόγια'!$R$15,"") | L16: =IF('Δρομολόγια'!$P$16,ROUND(ROUND('Δρομολόγια'!$F$16*100,0)*(100-$A16)/100,0)/100*(1-'Δρομολόγια'!$S$16)-'Δρομολόγια'!$R$16,"") | M16: =IF('Δρομολόγια'!$P$17,ROUND(ROUND('Δρομολόγια'!$F$17*100,0)*(100-$A16)/100,0)/100*(1-'Δρομολόγια'!$S$17)-'Δρομολόγια'!$R$17,"") | N16: =IF('Δρομολόγια'!$P$18,ROUND(ROUND('Δρομολόγια'!$F$18*100,0)*(100-$A16)/100,0)/100*(1-'Δρομολόγια'!$S$18)-'Δρομολόγια'!$R$18,"") | O16: =IF('Δρομολόγια'!$P$19,ROUND(ROUND('Δρομολόγια'!$F$19*100,0)*(100-$A16)/100,0)/100*(1-'Δρομολόγια'!$S$19)-'Δρομολόγια'!$R$19,"") | P16: =IF('Δρομολόγια'!$P$20,ROUND(ROUND('Δρομολόγια'!$F$20*100,0)*(100-$A16)/100,0)/100*(1-'Δρομολόγια'!$S$20)-'Δρομολόγια'!$R$20,"") | Q16: δέκα
A17: 11 | B17: =IF('Δρομολόγια'!$P$6,ROUND(ROUND('Δρομολόγια'!$F$6*100,0)*(100-$A17)/100,0)/100*(1-'Δρομολόγια'!$S$6)-'Δρομολόγια'!$R$6,"") | C17: =IF('Δρομολόγια'!$P$7,ROUND(ROUND('Δρομολόγια'!$F$7*100,0)*(100-$A17)/100,0)/100*(1-'Δρομολόγια'!$S$7)-'Δρομολόγια'!$R$7,"") | D17: =IF('Δρομολόγια'!$P$8,ROUND(ROUND('Δρομολόγια'!$F$8*100,0)*(100-$A17)/100,0)/100*(1-'Δρομολόγια'!$S$8)-'Δρομολόγια'!$R$8,"") | E17: =IF('Δρομολόγια'!$P$9,ROUND(ROUND('Δρομολόγια'!$F$9*100,0)*(100-$A17)/100,0)/100*(1-'Δρομολόγια'!$S$9)-'Δρομολόγια'!$R$9,"") | F17: =IF('Δρομολόγια'!$P$10,ROUND(ROUND('Δρομολόγια'!$F$10*100,0)*(100-$A17)/100,0)/100*(1-'Δρομολόγια'!$S$10)-'Δρομολόγια'!$R$10,"") | G17: =IF('Δρομολόγια'!$P$11,ROUND(ROUND('Δρομολόγια'!$F$11*100,0)*(100-$A17)/100,0)/100*(1-'Δρομολόγια'!$S$11)-'Δρομολόγια'!$R$11,"") | H17: =IF('Δρομολόγια'!$P$12,ROUND(ROUND('Δρομολόγια'!$F$12*100,0)*(100-$A17)/100,0)/100*(1-'Δρομολόγια'!$S$12)-'Δρομολόγια'!$R$12,"") | I17: =IF('Δρομολόγια'!$P$13,ROUND(ROUND('Δρομολόγια'!$F$13*100,0)*(100-$A17)/100,0)/100*(1-'Δρομολόγια'!$S$13)-'Δρομολόγια'!$R$13,"") | J17: =IF('Δρομολόγια'!$P$14,ROUND(ROUND('Δρομολόγια'!$F$14*100,0)*(100-$A17)/100,0)/100*(1-'Δρομολόγια'!$S$14)-'Δρομολόγια'!$R$14,"") | K17: =IF('Δρομολόγια'!$P$15,ROUND(ROUND('Δρομολόγια'!$F$15*100,0)*(100-$A17)/100,0)/100*(1-'Δρομολόγια'!$S$15)-'Δρομολόγια'!$R$15,"") | L17: =IF('Δρομολόγια'!$P$16,ROUND(ROUND('Δρομολόγια'!$F$16*100,0)*(100-$A17)/100,0)/100*(1-'Δρομολόγια'!$S$16)-'Δρομολόγια'!$R$16,"") | M17: =IF('Δρομολόγια'!$P$17,ROUND(ROUND('Δρομολόγια'!$F$17*100,0)*(100-$A17)/100,0)/100*(1-'Δρομολόγια'!$S$17)-'Δρομολόγια'!$R$17,"") | N17: =IF('Δρομολόγια'!$P$18,ROUND(ROUND('Δρομολόγια'!$F$18*100,0)*(100-$A17)/100,0)/100*(1-'Δρομολόγια'!$S$18)-'Δρομολόγια'!$R$18,"") | O17: =IF('Δρομολόγια'!$P$19,ROUND(ROUND('Δρομολόγια'!$F$19*100,0)*(100-$A17)/100,0)/100*(1-'Δρομολόγια'!$S$19)-'Δρομολόγια'!$R$19,"") | P17: =IF('Δρομολόγια'!$P$20,ROUND(ROUND('Δρομολόγια'!$F$20*100,0)*(100-$A17)/100,0)/100*(1-'Δρομολόγια'!$S$20)-'Δρομολόγια'!$R$20,"") | Q17: έντεκα
... A105: 99 | B105: =IF('Δρομολόγια'!$P$6,ROUND(ROUND('Δρομολόγια'!$F$6*100,0)*(100-$A105)/100,0)/100*(1-'Δρομολόγια'!$S$6)-'Δρομολόγια'!$R$6,"") | C105: =IF('Δρομολόγια'!$P$7,ROUND(ROUND('Δρομολόγια'!$F$7*100,0)*(100-$A105)/100,0)/100*(1-'Δρομολόγια'!$S$7)-'Δρομολόγια'!$R$7,"") | D105: =IF('Δρομολόγια'!$P$8,ROUND(ROUND('Δρομολόγια'!$F$8*100,0)*(100-$A105)/100,0)/100*(1-'Δρομολόγια'!$S$8)-'Δρομολόγια'!$R$8,"") | E105: =IF('Δρομολόγια'!$P$9,ROUND(ROUND('Δρομολόγια'!$F$9*100,0)*(100-$A105)/100,0)/100*(1-'Δρομολόγια'!$S$9)-'Δρομολόγια'!$R$9,"") | F105: =IF('Δρομολόγια'!$P$10,ROUND(ROUND('Δρομολόγια'!$F$10*100,0)*(100-$A105)/100,0)/100*(1-'Δρομολόγια'!$S$10)-'Δρομολόγια'!$R$10,"") | G105: =IF('Δρομολόγια'!$P$11,ROUND(ROUND('Δρομολόγια'!$F$11*100,0)*(100-$A105)/100,0)/100*(1-'Δρομολόγια'!$S$11)-'Δρομολόγια'!$R$11,"") | H105: =IF('Δρομολόγια'!$P$12,ROUND(ROUND('Δρομολόγια'!$F$12*100,0)*(100-$A105)/100,0)/100*(1-'Δρομολόγια'!$S$12)-'Δρομολόγια'!$R$12,"") | I105: =IF('Δρομολόγια'!$P$13,ROUND(ROUND('Δρομολόγια'!$F$13*100,0)*(100-$A105)/100,0)/100*(1-'Δρομολόγια'!$S$13)-'Δρομολόγια'!$R$13,"") | J105: =IF('Δρομολόγια'!$P$14,ROUND(ROUND('Δρομολόγια'!$F$14*100,0)*(100-$A105)/100,0)/100*(1-'Δρομολόγια'!$S$14)-'Δρομολόγια'!$R$14,"") | K105: =IF('Δρομολόγια'!$P$15,ROUND(ROUND('Δρομολόγια'!$F$15*100,0)*(100-$A105)/100,0)/100*(1-'Δρομολόγια'!$S$15)-'Δρομολόγια'!$R$15,"") | L105: =IF('Δρομολόγια'!$P$16,ROUND(ROUND('Δρομολόγια'!$F$16*100,0)*(100-$A105)/100,0)/100*(1-'Δρομολόγια'!$S$16)-'Δρομολόγια'!$R$16,"") | M105: =IF('Δρομολόγια'!$P$17,ROUND(ROUND('Δρομολόγια'!$F$17*100,0)*(100-$A105)/100,0)/100*(1-'Δρομολόγια'!$S$17)-'Δρομολόγια'!$R$17,"") | N105: =IF('Δρομολόγια'!$P$18,ROUND(ROUND('Δρομολόγια'!$F$18*100,0)*(100-$A105)/100,0)/100*(1-'Δρομολόγια'!$S$18)-'Δρομολόγια'!$R$18,"") | O105: =IF('Δρομολόγια'!$P$19,ROUND(ROUND('Δρομολόγια'!$F$19*100,0)*(100-$A105)/100,0)/100*(1-'Δρομολόγια'!$S$19)-'Δρομολόγια'!$R$19,"") | P105: =IF('Δρομολόγια'!$P$20,ROUND(ROUND('Δρομολόγια'!$F$20*100,0)*(100-$A105)/100,0)/100*(1-'Δρομολόγια'!$S$20)-'Δρομολόγια'!$R$20,"") | Q105: ενενήντα εννέα

Sheet Προσφορά
A1: Προσφορά: έλεγχος πριν την υποβολή από τον πελάτη
A2: Γράφεις ό,τι θα γράψει ο πελάτης στη φόρμα του ΕΣΗΔΗΣ και στο Υπόδειγμα. Τιμή = τιμή αναφοράς × (1 − ακέραια έκπτωση), 2 δεκαδικά, χωρίς ΦΠΑ (§4.3.2.1). Υποβάλλει ο πελάτης, όχι εμείς.
A5: # | B5: Κωδικός δρομολογίου | C5: Γραμμή στα Δρομολόγια | D5: Ομάδα | E5: Τιμή αναφοράς (€/ημέρα) | F5: Έκπτωση % (απόφαση πελάτη) | G5: Τιμή μετά την έκπτωση (υπολογίζεται) | H5: Τιμή στη φόρμα ΕΣΗΔΗΣ | I5: Τιμή στο Υπόδειγμα | J5: Σειρά προτεραιότητας | K5: Ολογράφως (για το Υπόδειγμα) | L5: Προϋπολογισμός χωρίς ΦΠΑ και προαίρεση (€) | M5: Έλεγχος
A6: 1 | C6: =IF(B6="","",IFERROR(MATCH(B6,'Δρομολόγια'!$C$6:$C$20,0),"")) | D6: =IF(ISNUMBER(C6),INDEX('Δρομολόγια'!$D$6:$D$20,C6)&"","") | E6: =IF(ISNUMBER(C6),INDEX('Δρομολόγια'!$F$6:$F$20,C6),"") | G6: =IF(AND(ISNUMBER(E6),ISNUMBER(F6)),ROUND(ROUND(E6*100,0)*(100-F6)/100,0)/100,"") | K6: =IF(AND(ISNUMBER(F6),F6=INT(F6),F6>=0,F6<=99),INDEX('Πλέγμα'!$Q$6:$Q$105,F6+1)&" τοις εκατό","") | L6: =IF(ISNUMBER(C6),INDEX('Δρομολόγια'!$H$6:$H$20,C6),"") | M6: =IF(B6="","",IF(NOT(ISNUMBER(C6)),"ΛΑΘΟΣ: ο κωδικός δεν υπάρχει στο φύλλο Δρομολόγια",IF(INDEX('Δρομολόγια'!$N$6:$N$20,C6)<>"ΝΑΙ","ΛΑΘΟΣ: δεν έχει καταγραφεί απόφαση ΝΑΙ του πελάτη (Δρομολόγια, στήλη N)",IF(NOT(AND(ISNUMBER(F6),F6=INT(F6),F6>=0,F6<=99)),"ΛΑΘΟΣ: η έκπτωση πρέπει να είναι ακέραιη, από 0 ως 99· δεκαδική στρογγυλοποιείται προς τα πάνω (§4.3.2.1)",IF(NOT(ISNUMBER(H6)),"ΛΑΘΟΣ: λείπει η τιμή της φόρμας",IF(OR(ABS(H6*100-ROUND(H6*100,0))>0.000001,ROUND(H6*100,0)<>ROUND(G6*100,0)),"ΛΑΘΟΣ: η τιμή της φόρμας δεν είναι τιμή αναφοράς × (1 − έκπτωση) με 2 δεκαδικά (§4.3.2.1)",IF(NOT(ISNUMBER(I6)),"ΛΑΘΟΣ: λείπει η τιμή του Υποδείγματος",IF(ROUND(I6*100,0)<>ROUND(H6*100,0),"ΛΑΘΟΣ: το Υπόδειγμα δεν συμφωνεί με τη φόρμα (§4.3.2.1)",IF(NOT(AND(ISNUMBER(J6),J6=INT(J6),J6>=1)),"ΛΑΘΟΣ: η σειρά προτεραιότητας πρέπει να είναι ακέραιος από 1 και πάνω (§4.3.2.1)",IF(COUNTIF($J$6:$J$20,J6)>1,"ΛΑΘΟΣ: ίδια σειρά προτεραιότητας σε δύο γραμμές",IF(COUNTIF($B$6:$B$20,B6)>1,"ΛΑΘΟΣ: το ίδιο δρομολόγιο δύο φορές",IF(AND(D6<>"",COUNTIFS($D$6:$D$20,D6,$F$6:$F$20,"<>"&F6)>0),"ΛΑΘΟΣ: στην ίδια ομάδα η έκπτωση πρέπει να είναι ίδια (§4.3.2.1)","OK"))))))))))))
